Workbook

Sheet Dashboard
C2: DEBT PAYOFF TRACKER | L2: StackedSheets
C4: ━━ PAYOFF METHOD ━━ | F4: ━━ EXTRA / MONTH ━━
C5: Snowball | F5: 200
I6: 🟢 = your input | K6: ■ = auto-calculated
C8: ━━ YOUR DEBT-FREE DATE ━━ | I8: ━━ PROGRESS ━━
C9: =IF(C5="Snowball",Snowball!CJ3,Avalanche!CJ3) | I9: =IF(Debts!I8>0,1-(IF(C5="Snowball",Snowball!CJ5,Avalanche!CJ5)/Debts!I8),0) | L9: paid off
C10: =IF(C5="Snowball",Snowball!CJ4,Avalanche!CJ4)&" months to freedom" | I10: ="$"&TEXT(Debts!I8-IF(C5="Snowball",Snowball!CJ5,Avalanche!CJ5),"#,##0")&" conquered so far"
C12: =Debts!I8 | F12: =Debts!I9+Dashboard!F5 | I12: =IF(C5="Snowball",Snowball!CJ2,Avalanche!CJ2) | L12: =Debts!I11
C13: ━━ TOTAL DEBT ━━ | F13: ━━ MONTHLY PAYMENT ━━ | I13: ━━ TOTAL INTEREST ━━ | L13: ━━ ACTIVE DEBTS ━━
C15: ● YOUR DEBTS
C16: DEBT NAME | E16: BALANCE | F16: APR | G16: MIN PMT | I16: PRIORITY | J16: STATUS | L16: TYPE
C17: =IF(Debts!B8="","",Debts!B8) | E17: =IF(Debts!C8="","",Debts!C8) | F17: =IF(Debts!D8="","",Debts!D8) | G17: =IF(Debts!E8="","",Debts!E8) | I17: =IF(Debts!B8="","",IF(Dashboard!$C$5="Snowball",Debts!I32,Debts!J32)) | J17: =IF(Debts!C8="","",IF(Debts!C8<=0,"✓ Paid","● Active")) | L17: =IF(Debts!F8="","",Debts!F8)
C18: =IF(Debts!B9="","",Debts!B9) | E18: =IF(Debts!C9="","",Debts!C9) | F18: =IF(Debts!D9="","",Debts!D9) | G18: =IF(Debts!E9="","",Debts!E9) | I18: =IF(Debts!B9="","",IF(Dashboard!$C$5="Snowball",Debts!I33,Debts!J33)) | J18: =IF(Debts!C9="","",IF(Debts!C9<=0,"✓ Paid","● Active")) | L18: =IF(Debts!F9="","",Debts!F9)
C19: =IF(Debts!B10="","",Debts!B10) | E19: =IF(Debts!C10="","",Debts!C10) | F19: =IF(Debts!D10="","",Debts!D10) | G19: =IF(Debts!E10="","",Debts!E10) | I19: =IF(Debts!B10="","",IF(Dashboard!$C$5="Snowball",Debts!I34,Debts!J34)) | J19: =IF(Debts!C10="","",IF(Debts!C10<=0,"✓ Paid","● Active")) | L19: =IF(Debts!F10="","",Debts!F10)
C20: =IF(Debts!B11="","",Debts!B11) | E20: =IF(Debts!C11="","",Debts!C11) | F20: =IF(Debts!D11="","",Debts!D11) | G20: =IF(Debts!E11="","",Debts!E11) | I20: =IF(Debts!B11="","",IF(Dashboard!$C$5="Snowball",Debts!I35,Debts!J35)) | J20: =IF(Debts!C11="","",IF(Debts!C11<=0,"✓ Paid","● Active")) | L20: =IF(Debts!F11="","",Debts!F11)
C21: =IF(Debts!B12="","",Debts!B12) | E21: =IF(Debts!C12="","",Debts!C12) | F21: =IF(Debts!D12="","",Debts!D12) | G21: =IF(Debts!E12="","",Debts!E12) | I21: =IF(Debts!B12="","",IF(Dashboard!$C$5="Snowball",Debts!I36,Debts!J36)) | J21: =IF(Debts!C12="","",IF(Debts!C12<=0,"✓ Paid","● Active")) | L21: =IF(Debts!F12="","",Debts!F12)
C22: =IF(Debts!B13="","",Debts!B13) | E22: =IF(Debts!C13="","",Debts!C13) | F22: =IF(Debts!D13="","",Debts!D13) | G22: =IF(Debts!E13="","",Debts!E13) | I22: =IF(Debts!B13="","",IF(Dashboard!$C$5="Snowball",Debts!I37,Debts!J37)) | J22: =IF(Debts!C13="","",IF(Debts!C13<=0,"✓ Paid","● Active")) | L22: =IF(Debts!F13="","",Debts!F13)
C23: =IF(Debts!B14="","",Debts!B14) | E23: =IF(Debts!C14="","",Debts!C14) | F23: =IF(Debts!D14="","",Debts!D14) | G23: =IF(Debts!E14="","",Debts!E14) | I23: =IF(Debts!B14="","",IF(Dashboard!$C$5="Snowball",Debts!I38,Debts!J38)) | J23: =IF(Debts!C14="","",IF(Debts!C14<=0,"✓ Paid","● Active")) | L23: =IF(Debts!F14="","",Debts!F14)
C24: =IF(Debts!B15="","",Debts!B15) | E24: =IF(Debts!C15="","",Debts!C15) | F24: =IF(Debts!D15="","",Debts!D15) | G24: =IF(Debts!E15="","",Debts!E15) | I24: =IF(Debts!B15="","",IF(Dashboard!$C$5="Snowball",Debts!I39,Debts!J39)) | J24: =IF(Debts!C15="","",IF(Debts!C15<=0,"✓ Paid","● Active")) | L24: =IF(Debts!F15="","",Debts!F15)
C25: =IF(Debts!B16="","",Debts!B16) | E25: =IF(Debts!C16="","",Debts!C16) | F25: =IF(Debts!D16="","",Debts!D16) | G25: =IF(Debts!E16="","",Debts!E16) | I25: =IF(Debts!B16="","",IF(Dashboard!$C$5="Snowball",Debts!I40,Debts!J40)) | J25: =IF(Debts!C16="","",IF(Debts!C16<=0,"✓ Paid","● Active")) | L25: =IF(Debts!F16="","",Debts!F16)
C26: =IF(Debts!B17="","",Debts!B17) | E26: =IF(Debts!C17="","",Debts!C17) | F26: =IF(Debts!D17="","",Debts!D17) | G26: =IF(Debts!E17="","",Debts!E17) | I26: =IF(Debts!B17="","",IF(Dashboard!$C$5="Snowball",Debts!I41,Debts!J41)) | J26: =IF(Debts!C17="","",IF(Debts!C17<=0,"✓ Paid","● Active")) | L26: =IF(Debts!F17="","",Debts!F17)
C27: =IF(Debts!B18="","",Debts!B18) | E27: =IF(Debts!C18="","",Debts!C18) | F27: =IF(Debts!D18="","",Debts!D18) | G27: =IF(Debts!E18="","",Debts!E18) | I27: =IF(Debts!B18="","",IF(Dashboard!$C$5="Snowball",Debts!I42,Debts!J42)) | J27: =IF(Debts!C18="","",IF(Debts!C18<=0,"✓ Paid","● Active")) | L27: =IF(Debts!F18="","",Debts!F18)
C28: =IF(Debts!B19="","",Debts!B19) | E28: =IF(Debts!C19="","",Debts!C19) | F28: =IF(Debts!D19="","",Debts!D19) | G28: =IF(Debts!E19="","",Debts!E19) | I28: =IF(Debts!B19="","",IF(Dashboard!$C$5="Snowball",Debts!I43,Debts!J43)) | J28: =IF(Debts!C19="","",IF(Debts!C19<=0,"✓ Paid","● Active")) | L28: =IF(Debts!F19="","",Debts!F19)
... C36: =IF(Debts!B27="","",Debts!B27) | E36: =IF(Debts!C27="","",Debts!C27) | F36: =IF(Debts!D27="","",Debts!D27) | G36: =IF(Debts!E27="","",Debts!E27) | I36: =IF(Debts!B27="","",IF(Dashboard!$C$5="Snowball",Debts!I51,Debts!J51)) | J36: =IF(Debts!C27="","",IF(Debts!C27<=0,"✓ Paid","● Active")) | L36: =IF(Debts!F27="","",Debts!F27)
C38: ● SNOWBALL VS AVALANCHE
F39: SNOWBALL | I39: AVALANCHE | L39: SAVINGS
C40: Total Interest | F40: =Snowball!CJ2 | I40: =Avalanche!CJ2 | L40: =ABS(F40-I40)
C41: Months to Freedom | F41: =Snowball!CJ4 | I41: =Avalanche!CJ4 | L41: =ABS(F41-I41)
C42: Free Date | F42: =Snowball!CJ3 | I42: =Avalanche!CJ3
C44: =IF(Avalanche!CJ2<Snowball!CJ2,"● Avalanche saves you $"&TEXT(Snowball!CJ2-Avalanche!CJ2,"#,##0")&" in interest","● Both methods cost the same")

Sheet Debts
B2: ● ENTER YOUR DEBTS
B4: Replace sample data with your own. Blue text = editable.
B5: Highlighted cells = your input · Everything else auto-calculates
B6: DEBT NAME | C6: BALANCE OWED | D6: APR (%) | E6: MIN MONTHLY PMT | F6: TYPE | G6: LENDER / NOTES | I6: ━━ SUMMARY ━━
I8: =SUMIF(C8:C27,">"&0,C8:C27) | J8: Total Debt
I9: =SUMIF(C8:C27,">"&0,E8:E27) | J9: Total Min Payments
I10: =IF(I8>0,SUMPRODUCT((C8:C27>0)*C8:C27*D8:D27)/I8,0) | J10: Weighted Avg APR
I11: =COUNTIF(C8:C27,">"&0) | J11: Active Debts
B30: — Calculation helpers — | I30: SnowRk | J30: AvalRk
I31: =IF(C8="",99,IF(C8<=0,99,RANK(C8,C$8:C$27,1)+COUNTIFS(C$8:C$27,C8,D$8:D$27,">"&D8))) | J31: =IF(C8="",99,IF(C8<=0,99,RANK(D8,D$8:D$27,0)+COUNTIFS(D$8:D$27,D8,C$8:C$27,"<"&C8)))
I32: =IF(C9="",99,IF(C9<=0,99,RANK(C9,C$8:C$27,1)+COUNTIFS(C$8:C$27,C9,D$8:D$27,">"&D9))) | J32: =IF(C9="",99,IF(C9<=0,99,RANK(D9,D$8:D$27,0)+COUNTIFS(D$8:D$27,D9,C$8:C$27,"<"&C9)))
I33: =IF(C10="",99,IF(C10<=0,99,RANK(C10,C$8:C$27,1)+COUNTIFS(C$8:C$27,C10,D$8:D$27,">"&D10))) | J33: =IF(C10="",99,IF(C10<=0,99,RANK(D10,D$8:D$27,0)+COUNTIFS(D$8:D$27,D10,C$8:C$27,"<"&C10)))
I34: =IF(C11="",99,IF(C11<=0,99,RANK(C11,C$8:C$27,1)+COUNTIFS(C$8:C$27,C11,D$8:D$27,">"&D11))) | J34: =IF(C11="",99,IF(C11<=0,99,RANK(D11,D$8:D$27,0)+COUNTIFS(D$8:D$27,D11,C$8:C$27,"<"&C11)))
I35: =IF(C12="",99,IF(C12<=0,99,RANK(C12,C$8:C$27,1)+COUNTIFS(C$8:C$27,C12,D$8:D$27,">"&D12))) | J35: =IF(C12="",99,IF(C12<=0,99,RANK(D12,D$8:D$27,0)+COUNTIFS(D$8:D$27,D12,C$8:C$27,"<"&C12)))
I36: =IF(C13="",99,IF(C13<=0,99,RANK(C13,C$8:C$27,1)+COUNTIFS(C$8:C$27,C13,D$8:D$27,">"&D13))) | J36: =IF(C13="",99,IF(C13<=0,99,RANK(D13,D$8:D$27,0)+COUNTIFS(D$8:D$27,D13,C$8:C$27,"<"&C13)))
I37: =IF(C14="",99,IF(C14<=0,99,RANK(C14,C$8:C$27,1)+COUNTIFS(C$8:C$27,C14,D$8:D$27,">"&D14))) | J37: =IF(C14="",99,IF(C14<=0,99,RANK(D14,D$8:D$27,0)+COUNTIFS(D$8:D$27,D14,C$8:C$27,"<"&C14)))
I38: =IF(C15="",99,IF(C15<=0,99,RANK(C15,C$8:C$27,1)+COUNTIFS(C$8:C$27,C15,D$8:D$27,">"&D15))) | J38: =IF(C15="",99,IF(C15<=0,99,RANK(D15,D$8:D$27,0)+COUNTIFS(D$8:D$27,D15,C$8:C$27,"<"&C15)))
I39: =IF(C16="",99,IF(C16<=0,99,RANK(C16,C$8:C$27,1)+COUNTIFS(C$8:C$27,C16,D$8:D$27,">"&D16))) | J39: =IF(C16="",99,IF(C16<=0,99,RANK(D16,D$8:D$27,0)+COUNTIFS(D$8:D$27,D16,C$8:C$27,"<"&C16)))
I40: =IF(C17="",99,IF(C17<=0,99,RANK(C17,C$8:C$27,1)+COUNTIFS(C$8:C$27,C17,D$8:D$27,">"&D17))) | J40: =IF(C17="",99,IF(C17<=0,99,RANK(D17,D$8:D$27,0)+COUNTIFS(D$8:D$27,D17,C$8:C$27,"<"&C17)))
I41: =IF(C18="",99,IF(C18<=0,99,RANK(C18,C$8:C$27,1)+COUNTIFS(C$8:C$27,C18,D$8:D$27,">"&D18))) | J41: =IF(C18="",99,IF(C18<=0,99,RANK(D18,D$8:D$27,0)+COUNTIFS(D$8:D$27,D18,C$8:C$27,"<"&C18)))
I42: =IF(C19="",99,IF(C19<=0,99,RANK(C19,C$8:C$27,1)+COUNTIFS(C$8:C$27,C19,D$8:D$27,">"&D19))) | J42: =IF(C19="",99,IF(C19<=0,99,RANK(D19,D$8:D$27,0)+COUNTIFS(D$8:D$27,D19,C$8:C$27,"<"&C19)))
... I50: =IF(C27="",99,IF(C27<=0,99,RANK(C27,C$8:C$27,1)+COUNTIFS(C$8:C$27,C27,D$8:D$27,">"&D27))) | J50: =IF(C27="",99,IF(C27<=0,99,RANK(D27,D$8:D$27,0)+COUNTIFS(D$8:D$27,D27,C$8:C$27,"<"&C27)))

Sheet Snowball
B1: ● SNOWBALL SCHEDULE
B2: Month | C2: Total Paid | D2: =IF(Debts!B8="","—",Debts!B8) | H2: =IF(Debts!B9="","—",Debts!B9) | L2: =IF(Debts!B10="","—",Debts!B10) | P2: =IF(Debts!B11="","—",Debts!B11) | T2: =IF(Debts!B12="","—",Debts!B12) | X2: =IF(Debts!B13="","—",Debts!B13) | AB2: =IF(Debts!B14="","—",Debts!B14) | AF2: =IF(Debts!B15="","—",Debts!B15) | AJ2: =IF(Debts!B16="","—",Debts!B16) | AN2: =IF(Debts!B17="","—",Debts!B17) | AR2: =IF(Debts!B18="","—",Debts!B18) | AV2: =IF(Debts!B19="","—",Debts!B19) | AZ2: =IF(Debts!B20="","—",Debts!B20) | BD2: =IF(Debts!B21="","—",Debts!B21) | BH2: =IF(Debts!B22="","—",Debts!B22) | BL2: =IF(Debts!B23="","—",Debts!B23) | BP2: =IF(Debts!B24="","—",Debts!B24) | BT2: =IF(Debts!B25="","—",Debts!B25) | BX2: =IF(Debts!B26="","—",Debts!B26) | CB2: =IF(Debts!B27="","—",Debts!B27) | CF2: Total Rem | CG2: Month Int | CH2: Cum Int | CJ2: =CH124
D3: Bal | E3: Int | F3: Pmt | G3: End | H3: Bal | I3: Int | J3: Pmt | K3: End | L3: Bal | M3: Int | N3: Pmt | O3: End | P3: Bal | Q3: Int | R3: Pmt | S3: End | T3: Bal | U3: Int | V3: Pmt | W3: End | X3: Bal | Y3: Int | Z3: Pmt | AA3: End | AB3: Bal | AC3: Int | AD3: Pmt | AE3: End | AF3: Bal | AG3: Int | AH3: Pmt | AI3: End | AJ3: Bal | AK3: Int | AL3: Pmt | AM3: End | AN3: Bal | AO3: Int | AP3: Pmt | AQ3: End | AR3: Bal | AS3: Int | AT3: Pmt | AU3: End | AV3: Bal | AW3: Int | AX3: Pmt | AY3: End | AZ3: Bal | BA3: Int | BB3: Pmt | BC3: End | BD3: Bal | BE3: Int | BF3: Pmt | BG3: End | BH3: Bal | BI3: Int | BJ3: Pmt | BK3: End | BL3: Bal | BM3: Int | BN3: Pmt | BO3: End | BP3: Bal | BQ3: Int | BR3: Pmt | BS3: End | BT3: Bal | BU3: Int | BV3: Pmt | BW3: End | BX3: Bal | BY3: Int | BZ3: Pmt | CA3: End | CB3: Bal | CC3: Int | CD3: Pmt | CE3: End | CJ3: =IFERROR(DATE(YEAR(TODAY()),MONTH(TODAY())+MATCH(TRUE(),INDEX(CF5:CF124<=0.01,0),0),DAY(TODAY())),"10+ years")
B4: 0 | C4: 0 | D4: =IF(Debts!C8="",0,Debts!C8) | E4: 0 | F4: 0 | G4: =IF(Debts!C8="",0,Debts!C8) | H4: =IF(Debts!C9="",0,Debts!C9) | I4: 0 | J4: 0 | K4: =IF(Debts!C9="",0,Debts!C9) | L4: =IF(Debts!C10="",0,Debts!C10) | M4: 0 | N4: 0 | O4: =IF(Debts!C10="",0,Debts!C10) | P4: =IF(Debts!C11="",0,Debts!C11) | Q4: 0 | R4: 0 | S4: =IF(Debts!C11="",0,Debts!C11) | T4: =IF(Debts!C12="",0,Debts!C12) | U4: 0 | V4: 0 | W4: =IF(Debts!C12="",0,Debts!C12) | X4: =IF(Debts!C13="",0,Debts!C13) | Y4: 0 | Z4: 0 | AA4: =IF(Debts!C13="",0,Debts!C13) | AB4: =IF(Debts!C14="",0,Debts!C14) | AC4: 0 | AD4: 0 | AE4: =IF(Debts!C14="",0,Debts!C14) | AF4: =IF(Debts!C15="",0,Debts!C15) | AG4: 0 | AH4: 0 | AI4: =IF(Debts!C15="",0,Debts!C15) | AJ4: =IF(Debts!C16="",0,Debts!C16) | AK4: 0 | AL4: 0 | AM4: =IF(Debts!C16="",0,Debts!C16) | AN4: =IF(Debts!C17="",0,Debts!C17) | AO4: 0 | AP4: 0 | AQ4: =IF(Debts!C17="",0,Debts!C17) | AR4: =IF(Debts!C18="",0,Debts!C18) | AS4: 0 | AT4: 0 | AU4: =IF(Debts!C18="",0,Debts!C18) | AV4: =IF(Debts!C19="",0,Debts!C19) | AW4: 0 | AX4: 0 | AY4: =IF(Debts!C19="",0,Debts!C19) | AZ4: =IF(Debts!C20="",0,Debts!C20) | BA4: 0 | BB4: 0 | BC4: =IF(Debts!C20="",0,Debts!C20) | BD4: =IF(Debts!C21="",0,Debts!C21) | BE4: 0 | BF4: 0 | BG4: =IF(Debts!C21="",0,Debts!C21) | BH4: =IF(Debts!C22="",0,Debts!C22) | BI4: 0 | BJ4: 0 | BK4: =IF(Debts!C22="",0,Debts!C22) | BL4: =IF(Debts!C23="",0,Debts!C23) | BM4: 0 | BN4: 0 | BO4: =IF(Debts!C23="",0,Debts!C23) | BP4: =IF(Debts!C24="",0,Debts!C24) | BQ4: 0 | BR4: 0 | BS4: =IF(Debts!C24="",0,Debts!C24) | BT4: =IF(Debts!C25="",0,Debts!C25) | BU4: 0 | BV4: 0 | BW4: =IF(Debts!C25="",0,Debts!C25) | BX4: =IF(Debts!C26="",0,Debts!C26) | BY4: 0 | BZ4: 0 | CA4: =IF(Debts!C26="",0,Debts!C26) | CB4: =IF(Debts!C27="",0,Debts!C27) | CC4: 0 | CD4: 0 | CE4: =IF(Debts!C27="",0,Debts!C27) | CF4: =G4+K4+O4+S4+W4+AA4+AE4+AI4+AM4+AQ4+AU4+AY4+BC4+BG4+BK4+BO4+BS4+BW4+CA4+CE4 | CG4: 0 | CH4: 0 | CJ4: =IFERROR(MATCH(TRUE(),INDEX(CF5:CF124<=0.01,0),0),120)
B5: 1 | C5: =F5+J5+N5+R5+V5+Z5+AD5+AH5+AL5+AP5+AT5+AX5+BB5+BF5+BJ5+BN5+BR5+BV5+BZ5+CD5 | D5: =G4 | E5: =IF(D5>0.005,D5*Debts!D8/12,0) | F5: 0 | G5: =MAX(0,D5+E5-F5) | H5: =K4 | I5: =IF(H5>0.005,H5*Debts!D9/12,0) | J5: 0 | K5: =MAX(0,H5+I5-J5) | L5: =O4 | M5: =IF(L5>0.005,L5*Debts!D10/12,0) | N5: 0 | O5: =MAX(0,L5+M5-N5) | P5: =S4 | Q5: =IF(P5>0.005,P5*Debts!D11/12,0) | R5: 0 | S5: =MAX(0,P5+Q5-R5) | T5: =W4 | U5: =IF(T5>0.005,T5*Debts!D12/12,0) | V5: 0 | W5: =MAX(0,T5+U5-V5) | X5: =AA4 | Y5: =IF(X5>0.005,X5*Debts!D13/12,0) | Z5: 0 | AA5: =MAX(0,X5+Y5-Z5) | AB5: =AE4 | AC5: =IF(AB5>0.005,AB5*Debts!D14/12,0) | AD5: 0 | AE5: =MAX(0,AB5+AC5-AD5) | AF5: =AI4 | AG5: =IF(AF5>0.005,AF5*Debts!D15/12,0) | AH5: 0 | AI5: =MAX(0,AF5+AG5-AH5) | AJ5: =AM4 | AK5: =IF(AJ5>0.005,AJ5*Debts!D16/12,0) | AL5: 0 | AM5: =MAX(0,AJ5+AK5-AL5) | AN5: =AQ4 | AO5: =IF(AN5>0.005,AN5*Debts!D17/12,0) | AP5: 0 | AQ5: =MAX(0,AN5+AO5-AP5) | AR5: =AU4 | AS5: =IF(AR5>0.005,AR5*Debts!D18/12,0) | AT5: 0 | AU5: =MAX(0,AR5+AS5-AT5) | AV5: =AY4 | AW5: =IF(AV5>0.005,AV5*Debts!D19/12,0) | AX5: 0 | AY5: =MAX(0,AV5+AW5-AX5) | AZ5: =BC4 | BA5: =IF(AZ5>0.005,AZ5*Debts!D20/12,0) | BB5: 0 | BC5: =MAX(0,AZ5+BA5-BB5) | BD5: =BG4 | BE5: =IF(BD5>0.005,BD5*Debts!D21/12,0) | BF5: 0 | BG5: =MAX(0,BD5+BE5-BF5) | BH5: =BK4 | BI5: =IF(BH5>0.005,BH5*Debts!D22/12,0) | BJ5: 0 | BK5: =MAX(0,BH5+BI5-BJ5) | BL5: =BO4 | BM5: =IF(BL5>0.005,BL5*Debts!D23/12,0) | BN5: 0 | BO5: =MAX(0,BL5+BM5-BN5) | BP5: =BS4 | BQ5: =IF(BP5>0.005,BP5*Debts!D24/12,0) | BR5: 0 | BS5: =MAX(0,BP5+BQ5-BR5) | BT5: =BW4 | BU5: =IF(BT5>0.005,BT5*Debts!D25/12,0) | BV5: 0 | BW5: =MAX(0,BT5+BU5-BV5) | BX5: =CA4 | BY5: =IF(BX5>0.005,BX5*Debts!D26/12,0) | BZ5: 0 | CA5: =MAX(0,BX5+BY5-BZ5) | CB5: =CE4 | CC5: =IF(CB5>0.005,CB5*Debts!D27/12,0) | CD5: 0 | CE5: =MAX(0,CB5+CC5-CD5) | CF5: =G5+K5+O5+S5+W5+AA5+AE5+AI5+AM5+AQ5+AU5+AY5+BC5+BG5+BK5+BO5+BS5+BW5+CA5+CE5 | CG5: =E5+I5+M5+Q5+U5+Y5+AC5+AG5+AK5+AO5+AS5+AW5+BA5+BE5+BI5+BM5+BQ5+BU5+BY5+CC5 | CH5: =CH4+CG5 | CJ5: =CF5
B6: 2 | C6: =F6+J6+N6+R6+V6+Z6+AD6+AH6+AL6+AP6+AT6+AX6+BB6+BF6+BJ6+BN6+BR6+BV6+BZ6+CD6 | D6: =G5 | E6: =IF(D6>0.005,D6*Debts!D8/12,0) | F6: 0 | G6: =MAX(0,D6+E6-F6) | H6: =K5 | I6: =IF(H6>0.005,H6*Debts!D9/12,0) | J6: 0 | K6: =MAX(0,H6+I6-J6) | L6: =O5 | M6: =IF(L6>0.005,L6*Debts!D10/12,0) | N6: 0 | O6: =MAX(0,L6+M6-N6) | P6: =S5 | Q6: =IF(P6>0.005,P6*Debts!D11/12,0) | R6: 0 | S6: =MAX(0,P6+Q6-R6) | T6: =W5 | U6: =IF(T6>0.005,T6*Debts!D12/12,0) | V6: 0 | W6: =MAX(0,T6+U6-V6) | X6: =AA5 | Y6: =IF(X6>0.005,X6*Debts!D13/12,0) | Z6: 0 | AA6: =MAX(0,X6+Y6-Z6) | AB6: =AE5 | AC6: =IF(AB6>0.005,AB6*Debts!D14/12,0) | AD6: 0 | AE6: =MAX(0,AB6+AC6-AD6) | AF6: =AI5 | AG6: =IF(AF6>0.005,AF6*Debts!D15/12,0) | AH6: 0 | AI6: =MAX(0,AF6+AG6-AH6) | AJ6: =AM5 | AK6: =IF(AJ6>0.005,AJ6*Debts!D16/12,0) | AL6: 0 | AM6: =MAX(0,AJ6+AK6-AL6) | AN6: =AQ5 | AO6: =IF(AN6>0.005,AN6*Debts!D17/12,0) | AP6: 0 | AQ6: =MAX(0,AN6+AO6-AP6) | AR6: =AU5 | AS6: =IF(AR6>0.005,AR6*Debts!D18/12,0) | AT6: 0 | AU6: =MAX(0,AR6+AS6-AT6) | AV6: =AY5 | AW6: =IF(AV6>0.005,AV6*Debts!D19/12,0) | AX6: 0 | AY6: =MAX(0,AV6+AW6-AX6) | AZ6: =BC5 | BA6: =IF(AZ6>0.005,AZ6*Debts!D20/12,0) | BB6: 0 | BC6: =MAX(0,AZ6+BA6-BB6) | BD6: =BG5 | BE6: =IF(BD6>0.005,BD6*Debts!D21/12,0) | BF6: 0 | BG6: =MAX(0,BD6+BE6-BF6) | BH6: =BK5 | BI6: =IF(BH6>0.005,BH6*Debts!D22/12,0) | BJ6: 0 | BK6: =MAX(0,BH6+BI6-BJ6) | BL6: =BO5 | BM6: =IF(BL6>0.005,BL6*Debts!D23/12,0) | BN6: 0 | BO6: =MAX(0,BL6+BM6-BN6) | BP6: =BS5 | BQ6: =IF(BP6>0.005,BP6*Debts!D24/12,0) | BR6: 0 | BS6: =MAX(0,BP6+BQ6-BR6) | BT6: =BW5 | BU6: =IF(BT6>0.005,BT6*Debts!D25/12,0) | BV6: 0 | BW6: =MAX(0,BT6+BU6-BV6) | BX6: =CA5 | BY6: =IF(BX6>0.005,BX6*Debts!D26/12,0) | BZ6: 0 | CA6: =MAX(0,BX6+BY6-BZ6) | CB6: =CE5 | CC6: =IF(CB6>0.005,CB6*Debts!D27/12,0) | CD6: 0 | CE6: =MAX(0,CB6+CC6-CD6) | CF6: =G6+K6+O6+S6+W6+AA6+AE6+AI6+AM6+AQ6+AU6+AY6+BC6+BG6+BK6+BO6+BS6+BW6+CA6+CE6 | CG6: =E6+I6+M6+Q6+U6+Y6+AC6+AG6+AK6+AO6+AS6+AW6+BA6+BE6+BI6+BM6+BQ6+BU6+BY6+CC6 | CH6: =CH5+CG6
B7: 3 | C7: =F7+J7+N7+R7+V7+Z7+AD7+AH7+AL7+AP7+AT7+AX7+BB7+BF7+BJ7+BN7+BR7+BV7+BZ7+CD7 | D7: =G6 | E7: =IF(D7>0.005,D7*Debts!D8/12,0) | F7: 0 | G7: =MAX(0,D7+E7-F7) | H7: =K6 | I7: =IF(H7>0.005,H7*Debts!D9/12,0) | J7: 0 | K7: =MAX(0,H7+I7-J7) | L7: =O6 | M7: =IF(L7>0.005,L7*Debts!D10/12,0) | N7: 0 | O7: =MAX(0,L7+M7-N7) | P7: =S6 | Q7: =IF(P7>0.005,P7*Debts!D11/12,0) | R7: 0 | S7: =MAX(0,P7+Q7-R7) | T7: =W6 | U7: =IF(T7>0.005,T7*Debts!D12/12,0) | V7: 0 | W7: =MAX(0,T7+U7-V7) | X7: =AA6 | Y7: =IF(X7>0.005,X7*Debts!D13/12,0) | Z7: 0 | AA7: =MAX(0,X7+Y7-Z7) | AB7: =AE6 | AC7: =IF(AB7>0.005,AB7*Debts!D14/12,0) | AD7: 0 | AE7: =MAX(0,AB7+AC7-AD7) | AF7: =AI6 | AG7: =IF(AF7>0.005,AF7*Debts!D15/12,0) | AH7: 0 | AI7: =MAX(0,AF7+AG7-AH7) | AJ7: =AM6 | AK7: =IF(AJ7>0.005,AJ7*Debts!D16/12,0) | AL7: 0 | AM7: =MAX(0,AJ7+AK7-AL7) | AN7: =AQ6 | AO7: =IF(AN7>0.005,AN7*Debts!D17/12,0) | AP7: 0 | AQ7: =MAX(0,AN7+AO7-AP7) | AR7: =AU6 | AS7: =IF(AR7>0.005,AR7*Debts!D18/12,0) | AT7: 0 | AU7: =MAX(0,AR7+AS7-AT7) | AV7: =AY6 | AW7: =IF(AV7>0.005,AV7*Debts!D19/12,0) | AX7: 0 | AY7: =MAX(0,AV7+AW7-AX7) | AZ7: =BC6 | BA7: =IF(AZ7>0.005,AZ7*Debts!D20/12,0) | BB7: 0 | BC7: =MAX(0,AZ7+BA7-BB7) | BD7: =BG6 | BE7: =IF(BD7>0.005,BD7*Debts!D21/12,0) | BF7: 0 | BG7: =MAX(0,BD7+BE7-BF7) | BH7: =BK6 | BI7: =IF(BH7>0.005,BH7*Debts!D22/12,0) | BJ7: 0 | BK7: =MAX(0,BH7+BI7-BJ7) | BL7: =BO6 | BM7: =IF(BL7>0.005,BL7*Debts!D23/12,0) | BN7: 0 | BO7: =MAX(0,BL7+BM7-BN7) | BP7: =BS6 | BQ7: =IF(BP7>0.005,BP7*Debts!D24/12,0) | BR7: 0 | BS7: =MAX(0,BP7+BQ7-BR7) | BT7: =BW6 | BU7: =IF(BT7>0.005,BT7*Debts!D25/12,0) | BV7: 0 | BW7: =MAX(0,BT7+BU7-BV7) | BX7: =CA6 | BY7: =IF(BX7>0.005,BX7*Debts!D26/12,0) | BZ7: 0 | CA7: =MAX(0,BX7+BY7-BZ7) | CB7: =CE6 | CC7: =IF(CB7>0.005,CB7*Debts!D27/12,0) | CD7: 0 | CE7: =MAX(0,CB7+CC7-CD7) | CF7: =G7+K7+O7+S7+W7+AA7+AE7+AI7+AM7+AQ7+AU7+AY7+BC7+BG7+BK7+BO7+BS7+BW7+CA7+CE7 | CG7: =E7+I7+M7+Q7+U7+Y7+AC7+AG7+AK7+AO7+AS7+AW7+BA7+BE7+BI7+BM7+BQ7+BU7+BY7+CC7 | CH7: =CH6+CG7
B8: 4 | C8: =F8+J8+N8+R8+V8+Z8+AD8+AH8+AL8+AP8+AT8+AX8+BB8+BF8+BJ8+BN8+BR8+BV8+BZ8+CD8 | D8: =G7 | E8: =IF(D8>0.005,D8*Debts!D8/12,0) | F8: 0 | G8: =MAX(0,D8+E8-F8) | H8: =K7 | I8: =IF(H8>0.005,H8*Debts!D9/12,0) | J8: 0 | K8: =MAX(0,H8+I8-J8) | L8: =O7 | M8: =IF(L8>0.005,L8*Debts!D10/12,0) | N8: 0 | O8: =MAX(0,L8+M8-N8) | P8: =S7 | Q8: =IF(P8>0.005,P8*Debts!D11/12,0) | R8: 0 | S8: =MAX(0,P8+Q8-R8) | T8: =W7 | U8: =IF(T8>0.005,T8*Debts!D12/12,0) | V8: 0 | W8: =MAX(0,T8+U8-V8) | X8: =AA7 | Y8: =IF(X8>0.005,X8*Debts!D13/12,0) | Z8: 0 | AA8: =MAX(0,X8+Y8-Z8) | AB8: =AE7 | AC8: =IF(AB8>0.005,AB8*Debts!D14/12,0) | AD8: 0 | AE8: =MAX(0,AB8+AC8-AD8) | AF8: =AI7 | AG8: =IF(AF8>0.005,AF8*Debts!D15/12,0) | AH8: 0 | AI8: =MAX(0,AF8+AG8-AH8) | AJ8: =AM7 | AK8: =IF(AJ8>0.005,AJ8*Debts!D16/12,0) | AL8: 0 | AM8: =MAX(0,AJ8+AK8-AL8) | AN8: =AQ7 | AO8: =IF(AN8>0.005,AN8*Debts!D17/12,0) | AP8: 0 | AQ8: =MAX(0,AN8+AO8-AP8) | AR8: =AU7 | AS8: =IF(AR8>0.005,AR8*Debts!D18/12,0) | AT8: 0 | AU8: =MAX(0,AR8+AS8-AT8) | AV8: =AY7 | AW8: =IF(AV8>0.005,AV8*Debts!D19/12,0) | AX8: 0 | AY8: =MAX(0,AV8+AW8-AX8) | AZ8: =BC7 | BA8: =IF(AZ8>0.005,AZ8*Debts!D20/12,0) | BB8: 0 | BC8: =MAX(0,AZ8+BA8-BB8) | BD8: =BG7 | BE8: =IF(BD8>0.005,BD8*Debts!D21/12,0) | BF8: 0 | BG8: =MAX(0,BD8+BE8-BF8) | BH8: =BK7 | BI8: =IF(BH8>0.005,BH8*Debts!D22/12,0) | BJ8: 0 | BK8: =MAX(0,BH8+BI8-BJ8) | BL8: =BO7 | BM8: =IF(BL8>0.005,BL8*Debts!D23/12,0) | BN8: 0 | BO8: =MAX(0,BL8+BM8-BN8) | BP8: =BS7 | BQ8: =IF(BP8>0.005,BP8*Debts!D24/12,0) | BR8: 0 | BS8: =MAX(0,BP8+BQ8-BR8) | BT8: =BW7 | BU8: =IF(BT8>0.005,BT8*Debts!D25/12,0) | BV8: 0 | BW8: =MAX(0,BT8+BU8-BV8) | BX8: =CA7 | BY8: =IF(BX8>0.005,BX8*Debts!D26/12,0) | BZ8: 0 | CA8: =MAX(0,BX8+BY8-BZ8) | CB8: =CE7 | CC8: =IF(CB8>0.005,CB8*Debts!D27/12,0) | CD8: 0 | CE8: =MAX(0,CB8+CC8-CD8) | CF8: =G8+K8+O8+S8+W8+AA8+AE8+AI8+AM8+AQ8+AU8+AY8+BC8+BG8+BK8+BO8+BS8+BW8+CA8+CE8 | CG8: =E8+I8+M8+Q8+U8+Y8+AC8+AG8+AK8+AO8+AS8+AW8+BA8+BE8+BI8+BM8+BQ8+BU8+BY8+CC8 | CH8: =CH7+CG8
B9: 5 | C9: =F9+J9+N9+R9+V9+Z9+AD9+AH9+AL9+AP9+AT9+AX9+BB9+BF9+BJ9+BN9+BR9+BV9+BZ9+CD9 | D9: =G8 | E9: =IF(D9>0.005,D9*Debts!D8/12,0) | F9: 0 | G9: =MAX(0,D9+E9-F9) | H9: =K8 | I9: =IF(H9>0.005,H9*Debts!D9/12,0) | J9: 0 | K9: =MAX(0,H9+I9-J9) | L9: =O8 | M9: =IF(L9>0.005,L9*Debts!D10/12,0) | N9: 0 | O9: =MAX(0,L9+M9-N9) | P9: =S8 | Q9: =IF(P9>0.005,P9*Debts!D11/12,0) | R9: 0 | S9: =MAX(0,P9+Q9-R9) | T9: =W8 | U9: =IF(T9>0.005,T9*Debts!D12/12,0) | V9: 0 | W9: =MAX(0,T9+U9-V9) | X9: =AA8 | Y9: =IF(X9>0.005,X9*Debts!D13/12,0) | Z9: 0 | AA9: =MAX(0,X9+Y9-Z9) | AB9: =AE8 | AC9: =IF(AB9>0.005,AB9*Debts!D14/12,0) | AD9: 0 | AE9: =MAX(0,AB9+AC9-AD9) | AF9: =AI8 | AG9: =IF(AF9>0.005,AF9*Debts!D15/12,0) | AH9: 0 | AI9: =MAX(0,AF9+AG9-AH9) | AJ9: =AM8 | AK9: =IF(AJ9>0.005,AJ9*Debts!D16/12,0) | AL9: 0 | AM9: =MAX(0,AJ9+AK9-AL9) | AN9: =AQ8 | AO9: =IF(AN9>0.005,AN9*Debts!D17/12,0) | AP9: 0 | AQ9: =MAX(0,AN9+AO9-AP9) | AR9: =AU8 | AS9: =IF(AR9>0.005,AR9*Debts!D18/12,0) | AT9: 0 | AU9: =MAX(0,AR9+AS9-AT9) | AV9: =AY8 | AW9: =IF(AV9>0.005,AV9*Debts!D19/12,0) | AX9: 0 | AY9: =MAX(0,AV9+AW9-AX9) | AZ9: =BC8 | BA9: =IF(AZ9>0.005,AZ9*Debts!D20/12,0) | BB9: 0 | BC9: =MAX(0,AZ9+BA9-BB9) | BD9: =BG8 | BE9: =IF(BD9>0.005,BD9*Debts!D21/12,0) | BF9: 0 | BG9: =MAX(0,BD9+BE9-BF9) | BH9: =BK8 | BI9: =IF(BH9>0.005,BH9*Debts!D22/12,0) | BJ9: 0 | BK9: =MAX(0,BH9+BI9-BJ9) | BL9: =BO8 | BM9: =IF(BL9>0.005,BL9*Debts!D23/12,0) | BN9: 0 | BO9: =MAX(0,BL9+BM9-BN9) | BP9: =BS8 | BQ9: =IF(BP9>0.005,BP9*Debts!D24/12,0) | BR9: 0 | BS9: =MAX(0,BP9+BQ9-BR9) | BT9: =BW8 | BU9: =IF(BT9>0.005,BT9*Debts!D25/12,0) | BV9: 0 | BW9: =MAX(0,BT9+BU9-BV9) | BX9: =CA8 | BY9: =IF(BX9>0.005,BX9*Debts!D26/12,0) | BZ9: 0 | CA9: =MAX(0,BX9+BY9-BZ9) | CB9: =CE8 | CC9: =IF(CB9>0.005,CB9*Debts!D27/12,0) | CD9: 0 | CE9: =MAX(0,CB9+CC9-CD9) | CF9: =G9+K9+O9+S9+W9+AA9+AE9+AI9+AM9+AQ9+AU9+AY9+BC9+BG9+BK9+BO9+BS9+BW9+CA9+CE9 | CG9: =E9+I9+M9+Q9+U9+Y9+AC9+AG9+AK9+AO9+AS9+AW9+BA9+BE9+BI9+BM9+BQ9+BU9+BY9+CC9 | CH9: =CH8+CG9
B10: 6 | C10: =F10+J10+N10+R10+V10+Z10+AD10+AH10+AL10+AP10+AT10+AX10+BB10+BF10+BJ10+BN10+BR10+BV10+BZ10+CD10 | D10: =G9 | E10: =IF(D10>0.005,D10*Debts!D8/12,0) | F10: 0 | G10: =MAX(0,D10+E10-F10) | H10: =K9 | I10: =IF(H10>0.005,H10*Debts!D9/12,0) | J10: 0 | K10: =MAX(0,H10+I10-J10) | L10: =O9 | M10: =IF(L10>0.005,L10*Debts!D10/12,0) | N10: 0 | O10: =MAX(0,L10+M10-N10) | P10: =S9 | Q10: =IF(P10>0.005,P10*Debts!D11/12,0) | R10: 0 | S10: =MAX(0,P10+Q10-R10) | T10: =W9 | U10: =IF(T10>0.005,T10*Debts!D12/12,0) | V10: 0 | W10: =MAX(0,T10+U10-V10) | X10: =AA9 | Y10: =IF(X10>0.005,X10*Debts!D13/12,0) | Z10: 0 | AA10: =MAX(0,X10+Y10-Z10) | AB10: =AE9 | AC10: =IF(AB10>0.005,AB10*Debts!D14/12,0) | AD10: 0 | AE10: =MAX(0,AB10+AC10-AD10) | AF10: =AI9 | AG10: =IF(AF10>0.005,AF10*Debts!D15/12,0) | AH10: 0 | AI10: =MAX(0,AF10+AG10-AH10) | AJ10: =AM9 | AK10: =IF(AJ10>0.005,AJ10*Debts!D16/12,0) | AL10: 0 | AM10: =MAX(0,AJ10+AK10-AL10) | AN10: =AQ9 | AO10: =IF(AN10>0.005,AN10*Debts!D17/12,0) | AP10: 0 | AQ10: =MAX(0,AN10+AO10-AP10) | AR10: =AU9 | AS10: =IF(AR10>0.005,AR10*Debts!D18/12,0) | AT10: 0 | AU10: =MAX(0,AR10+AS10-AT10) | AV10: =AY9 | AW10: =IF(AV10>0.005,AV10*Debts!D19/12,0) | AX10: 0 | AY10: =MAX(0,AV10+AW10-AX10) | AZ10: =BC9 | BA10: =IF(AZ10>0.005,AZ10*Debts!D20/12,0) | BB10: 0 | BC10: =MAX(0,AZ10+BA10-BB10) | BD10: =BG9 | BE10: =IF(BD10>0.005,BD10*Debts!D21/12,0) | BF10: 0 | BG10: =MAX(0,BD10+BE10-BF10) | BH10: =BK9 | BI10: =IF(BH10>0.005,BH10*Debts!D22/12,0) | BJ10: 0 | BK10: =MAX(0,BH10+BI10-BJ10) | BL10: =BO9 | BM10: =IF(BL10>0.005,BL10*Debts!D23/12,0) | BN10: 0 | BO10: =MAX(0,BL10+BM10-BN10) | BP10: =BS9 | BQ10: =IF(BP10>0.005,BP10*Debts!D24/12,0) | BR10: 0 | BS10: =MAX(0,BP10+BQ10-BR10) | BT10: =BW9 | BU10: =IF(BT10>0.005,BT10*Debts!D25/12,0) | BV10: 0 | BW10: =MAX(0,BT10+BU10-BV10) | BX10: =CA9 | BY10: =IF(BX10>0.005,BX10*Debts!D26/12,0) | BZ10: 0 | CA10: =MAX(0,BX10+BY10-BZ10) | CB10: =CE9 | CC10: =IF(CB10>0.005,CB10*Debts!D27/12,0) | CD10: 0 | CE10: =MAX(0,CB10+CC10-CD10) | CF10: =G10+K10+O10+S10+W10+AA10+AE10+AI10+AM10+AQ10+AU10+AY10+BC10+BG10+BK10+BO10+BS10+BW10+CA10+CE10 | CG10: =E10+I10+M10+Q10+U10+Y10+AC10+AG10+AK10+AO10+AS10+AW10+BA10+BE10+BI10+BM10+BQ10+BU10+BY10+CC10 | CH10: =CH9+CG10
B11: 7 | C11: =F11+J11+N11+R11+V11+Z11+AD11+AH11+AL11+AP11+AT11+AX11+BB11+BF11+BJ11+BN11+BR11+BV11+BZ11+CD11 | D11: =G10 | E11: =IF(D11>0.005,D11*Debts!D8/12,0) | F11: 0 | G11: =MAX(0,D11+E11-F11) | H11: =K10 | I11: =IF(H11>0.005,H11*Debts!D9/12,0) | J11: 0 | K11: =MAX(0,H11+I11-J11) | L11: =O10 | M11: =IF(L11>0.005,L11*Debts!D10/12,0) | N11: 0 | O11: =MAX(0,L11+M11-N11) | P11: =S10 | Q11: =IF(P11>0.005,P11*Debts!D11/12,0) | R11: 0 | S11: =MAX(0,P11+Q11-R11) | T11: =W10 | U11: =IF(T11>0.005,T11*Debts!D12/12,0) | V11: 0 | W11: =MAX(0,T11+U11-V11) | X11: =AA10 | Y11: =IF(X11>0.005,X11*Debts!D13/12,0) | Z11: 0 | AA11: =MAX(0,X11+Y11-Z11) | AB11: =AE10 | AC11: =IF(AB11>0.005,AB11*Debts!D14/12,0) | AD11: 0 | AE11: =MAX(0,AB11+AC11-AD11) | AF11: =AI10 | AG11: =IF(AF11>0.005,AF11*Debts!D15/12,0) | AH11: 0 | AI11: =MAX(0,AF11+AG11-AH11) | AJ11: =AM10 | AK11: =IF(AJ11>0.005,AJ11*Debts!D16/12,0) | AL11: 0 | AM11: =MAX(0,AJ11+AK11-AL11) | AN11: =AQ10 | AO11: =IF(AN11>0.005,AN11*Debts!D17/12,0) | AP11: 0 | AQ11: =MAX(0,AN11+AO11-AP11) | AR11: =AU10 | AS11: =IF(AR11>0.005,AR11*Debts!D18/12,0) | AT11: 0 | AU11: =MAX(0,AR11+AS11-AT11) | AV11: =AY10 | AW11: =IF(AV11>0.005,AV11*Debts!D19/12,0) | AX11: 0 | AY11: =MAX(0,AV11+AW11-AX11) | AZ11: =BC10 | BA11: =IF(AZ11>0.005,AZ11*Debts!D20/12,0) | BB11: 0 | BC11: =MAX(0,AZ11+BA11-BB11) | BD11: =BG10 | BE11: =IF(BD11>0.005,BD11*Debts!D21/12,0) | BF11: 0 | BG11: =MAX(0,BD11+BE11-BF11) | BH11: =BK10 | BI11: =IF(BH11>0.005,BH11*Debts!D22/12,0) | BJ11: 0 | BK11: =MAX(0,BH11+BI11-BJ11) | BL11: =BO10 | BM11: =IF(BL11>0.005,BL11*Debts!D23/12,0) | BN11: 0 | BO11: =MAX(0,BL11+BM11-BN11) | BP11: =BS10 | BQ11: =IF(BP11>0.005,BP11*Debts!D24/12,0) | BR11: 0 | BS11: =MAX(0,BP11+BQ11-BR11) | BT11: =BW10 | BU11: =IF(BT11>0.005,BT11*Debts!D25/12,0) | BV11: 0 | BW11: =MAX(0,BT11+BU11-BV11) | BX11: =CA10 | BY11: =IF(BX11>0.005,BX11*Debts!D26/12,0) | BZ11: 0 | CA11: =MAX(0,BX11+BY11-BZ11) | CB11: =CE10 | CC11: =IF(CB11>0.005,CB11*Debts!D27/12,0) | CD11: 0 | CE11: =MAX(0,CB11+CC11-CD11) | CF11: =G11+K11+O11+S11+W11+AA11+AE11+AI11+AM11+AQ11+AU11+AY11+BC11+BG11+BK11+BO11+BS11+BW11+CA11+CE11 | CG11: =E11+I11+M11+Q11+U11+Y11+AC11+AG11+AK11+AO11+AS11+AW11+BA11+BE11+BI11+BM11+BQ11+BU11+BY11+CC11 | CH11: =CH10+CG11
B12: 8 | C12: =F12+J12+N12+R12+V12+Z12+AD12+AH12+AL12+AP12+AT12+AX12+BB12+BF12+BJ12+BN12+BR12+BV12+BZ12+CD12 | D12: =G11 | E12: =IF(D12>0.005,D12*Debts!D8/12,0) | F12: 0 | G12: =MAX(0,D12+E12-F12) | H12: =K11 | I12: =IF(H12>0.005,H12*Debts!D9/12,0) | J12: 0 | K12: =MAX(0,H12+I12-J12) | L12: =O11 | M12: =IF(L12>0.005,L12*Debts!D10/12,0) | N12: 0 | O12: =MAX(0,L12+M12-N12) | P12: =S11 | Q12: =IF(P12>0.005,P12*Debts!D11/12,0) | R12: 0 | S12: =MAX(0,P12+Q12-R12) | T12: =W11 | U12: =IF(T12>0.005,T12*Debts!D12/12,0) | V12: 0 | W12: =MAX(0,T12+U12-V12) | X12: =AA11 | Y12: =IF(X12>0.005,X12*Debts!D13/12,0) | Z12: 0 | AA12: =MAX(0,X12+Y12-Z12) | AB12: =AE11 | AC12: =IF(AB12>0.005,AB12*Debts!D14/12,0) | AD12: 0 | AE12: =MAX(0,AB12+AC12-AD12) | AF12: =AI11 | AG12: =IF(AF12>0.005,AF12*Debts!D15/12,0) | AH12: 0 | AI12: =MAX(0,AF12+AG12-AH12) | AJ12: =AM11 | AK12: =IF(AJ12>0.005,AJ12*Debts!D16/12,0) | AL12: 0 | AM12: =MAX(0,AJ12+AK12-AL12) | AN12: =AQ11 | AO12: =IF(AN12>0.005,AN12*Debts!D17/12,0) | AP12: 0 | AQ12: =MAX(0,AN12+AO12-AP12) | AR12: =AU11 | AS12: =IF(AR12>0.005,AR12*Debts!D18/12,0) | AT12: 0 | AU12: =MAX(0,AR12+AS12-AT12) | AV12: =AY11 | AW12: =IF(AV12>0.005,AV12*Debts!D19/12,0) | AX12: 0 | AY12: =MAX(0,AV12+AW12-AX12) | AZ12: =BC11 | BA12: =IF(AZ12>0.005,AZ12*Debts!D20/12,0) | BB12: 0 | BC12: =MAX(0,AZ12+BA12-BB12) | BD12: =BG11 | BE12: =IF(BD12>0.005,BD12*Debts!D21/12,0) | BF12: 0 | BG12: =MAX(0,BD12+BE12-BF12) | BH12: =BK11 | BI12: =IF(BH12>0.005,BH12*Debts!D22/12,0) | BJ12: 0 | BK12: =MAX(0,BH12+BI12-BJ12) | BL12: =BO11 | BM12: =IF(BL12>0.005,BL12*Debts!D23/12,0) | BN12: 0 | BO12: =MAX(0,BL12+BM12-BN12) | BP12: =BS11 | BQ12: =IF(BP12>0.005,BP12*Debts!D24/12,0) | BR12: 0 | BS12: =MAX(0,BP12+BQ12-BR12) | BT12: =BW11 | BU12: =IF(BT12>0.005,BT12*Debts!D25/12,0) | BV12: 0 | BW12: =MAX(0,BT12+BU12-BV12) | BX12: =CA11 | BY12: =IF(BX12>0.005,BX12*Debts!D26/12,0) | BZ12: 0 | CA12: =MAX(0,BX12+BY12-BZ12) | CB12: =CE11 | CC12: =IF(CB12>0.005,CB12*Debts!D27/12,0) | CD12: 0 | CE12: =MAX(0,CB12+CC12-CD12) | CF12: =G12+K12+O12+S12+W12+AA12+AE12+AI12+AM12+AQ12+AU12+AY12+BC12+BG12+BK12+BO12+BS12+BW12+CA12+CE12 | CG12: =E12+I12+M12+Q12+U12+Y12+AC12+AG12+AK12+AO12+AS12+AW12+BA12+BE12+BI12+BM12+BQ12+BU12+BY12+CC12 | CH12: =CH11+CG12
B13: 9 | C13: =F13+J13+N13+R13+V13+Z13+AD13+AH13+AL13+AP13+AT13+AX13+BB13+BF13+BJ13+BN13+BR13+BV13+BZ13+CD13 | D13: =G12 | E13: =IF(D13>0.005,D13*Debts!D8/12,0) | F13: 0 | G13: =MAX(0,D13+E13-F13) | H13: =K12 | I13: =IF(H13>0.005,H13*Debts!D9/12,0) | J13: 0 | K13: =MAX(0,H13+I13-J13) | L13: =O12 | M13: =IF(L13>0.005,L13*Debts!D10/12,0) | N13: 0 | O13: =MAX(0,L13+M13-N13) | P13: =S12 | Q13: =IF(P13>0.005,P13*Debts!D11/12,0) | R13: 0 | S13: =MAX(0,P13+Q13-R13) | T13: =W12 | U13: =IF(T13>0.005,T13*Debts!D12/12,0) | V13: 0 | W13: =MAX(0,T13+U13-V13) | X13: =AA12 | Y13: =IF(X13>0.005,X13*Debts!D13/12,0) | Z13: 0 | AA13: =MAX(0,X13+Y13-Z13) | AB13: =AE12 | AC13: =IF(AB13>0.005,AB13*Debts!D14/12,0) | AD13: 0 | AE13: =MAX(0,AB13+AC13-AD13) | AF13: =AI12 | AG13: =IF(AF13>0.005,AF13*Debts!D15/12,0) | AH13: 0 | AI13: =MAX(0,AF13+AG13-AH13) | AJ13: =AM12 | AK13: =IF(AJ13>0.005,AJ13*Debts!D16/12,0) | AL13: 0 | AM13: =MAX(0,AJ13+AK13-AL13) | AN13: =AQ12 | AO13: =IF(AN13>0.005,AN13*Debts!D17/12,0) | AP13: 0 | AQ13: =MAX(0,AN13+AO13-AP13) | AR13: =AU12 | AS13: =IF(AR13>0.005,AR13*Debts!D18/12,0) | AT13: 0 | AU13: =MAX(0,AR13+AS13-AT13) | AV13: =AY12 | AW13: =IF(AV13>0.005,AV13*Debts!D19/12,0) | AX13: 0 | AY13: =MAX(0,AV13+AW13-AX13) | AZ13: =BC12 | BA13: =IF(AZ13>0.005,AZ13*Debts!D20/12,0) | BB13: 0 | BC13: =MAX(0,AZ13+BA13-BB13) | BD13: =BG12 | BE13: =IF(BD13>0.005,BD13*Debts!D21/12,0) | BF13: 0 | BG13: =MAX(0,BD13+BE13-BF13) | BH13: =BK12 | BI13: =IF(BH13>0.005,BH13*Debts!D22/12,0) | BJ13: 0 | BK13: =MAX(0,BH13+BI13-BJ13) | BL13: =BO12 | BM13: =IF(BL13>0.005,BL13*Debts!D23/12,0) | BN13: 0 | BO13: =MAX(0,BL13+BM13-BN13) | BP13: =BS12 | BQ13: =IF(BP13>0.005,BP13*Debts!D24/12,0) | BR13: 0 | BS13: =MAX(0,BP13+BQ13-BR13) | BT13: =BW12 | BU13: =IF(BT13>0.005,BT13*Debts!D25/12,0) | BV13: 0 | BW13: =MAX(0,BT13+BU13-BV13) | BX13: =CA12 | BY13: =IF(BX13>0.005,BX13*Debts!D26/12,0) | BZ13: 0 | CA13: =MAX(0,BX13+BY13-BZ13) | CB13: =CE12 | CC13: =IF(CB13>0.005,CB13*Debts!D27/12,0) | CD13: 0 | CE13: =MAX(0,CB13+CC13-CD13) | CF13: =G13+K13+O13+S13+W13+AA13+AE13+AI13+AM13+AQ13+AU13+AY13+BC13+BG13+BK13+BO13+BS13+BW13+CA13+CE13 | CG13: =E13+I13+M13+Q13+U13+Y13+AC13+AG13+AK13+AO13+AS13+AW13+BA13+BE13+BI13+BM13+BQ13+BU13+BY13+CC13 | CH13: =CH12+CG13
B14: 10 | C14: =F14+J14+N14+R14+V14+Z14+AD14+AH14+AL14+AP14+AT14+AX14+BB14+BF14+BJ14+BN14+BR14+BV14+BZ14+CD14 | D14: =G13 | E14: =IF(D14>0.005,D14*Debts!D8/12,0) | F14: 0 | G14: =MAX(0,D14+E14-F14) | H14: =K13 | I14: =IF(H14>0.005,H14*Debts!D9/12,0) | J14: 0 | K14: =MAX(0,H14+I14-J14) | L14: =O13 | M14: =IF(L14>0.005,L14*Debts!D10/12,0) | N14: 0 | O14: =MAX(0,L14+M14-N14) | P14: =S13 | Q14: =IF(P14>0.005,P14*Debts!D11/12,0) | R14: 0 | S14: =MAX(0,P14+Q14-R14) | T14: =W13 | U14: =IF(T14>0.005,T14*Debts!D12/12,0) | V14: 0 | W14: =MAX(0,T14+U14-V14) | X14: =AA13 | Y14: =IF(X14>0.005,X14*Debts!D13/12,0) | Z14: 0 | AA14: =MAX(0,X14+Y14-Z14) | AB14: =AE13 | AC14: =IF(AB14>0.005,AB14*Debts!D14/12,0) | AD14: 0 | AE14: =MAX(0,AB14+AC14-AD14) | AF14: =AI13 | AG14: =IF(AF14>0.005,AF14*Debts!D15/12,0) | AH14: 0 | AI14: =MAX(0,AF14+AG14-AH14) | AJ14: =AM13 | AK14: =IF(AJ14>0.005,AJ14*Debts!D16/12,0) | AL14: 0 | AM14: =MAX(0,AJ14+AK14-AL14) | AN14: =AQ13 | AO14: =IF(AN14>0.005,AN14*Debts!D17/12,0) | AP14: 0 | AQ14: =MAX(0,AN14+AO14-AP14) | AR14: =AU13 | AS14: =IF(AR14>0.005,AR14*Debts!D18/12,0) | AT14: 0 | AU14: =MAX(0,AR14+AS14-AT14) | AV14: =AY13 | AW14: =IF(AV14>0.005,AV14*Debts!D19/12,0) | AX14: 0 | AY14: =MAX(0,AV14+AW14-AX14) | AZ14: =BC13 | BA14: =IF(AZ14>0.005,AZ14*Debts!D20/12,0) | BB14: 0 | BC14: =MAX(0,AZ14+BA14-BB14) | BD14: =BG13 | BE14: =IF(BD14>0.005,BD14*Debts!D21/12,0) | BF14: 0 | BG14: =MAX(0,BD14+BE14-BF14) | BH14: =BK13 | BI14: =IF(BH14>0.005,BH14*Debts!D22/12,0) | BJ14: 0 | BK14: =MAX(0,BH14+BI14-BJ14) | BL14: =BO13 | BM14: =IF(BL14>0.005,BL14*Debts!D23/12,0) | BN14: 0 | BO14: =MAX(0,BL14+BM14-BN14) | BP14: =BS13 | BQ14: =IF(BP14>0.005,BP14*Debts!D24/12,0) | BR14: 0 | BS14: =MAX(0,BP14+BQ14-BR14) | BT14: =BW13 | BU14: =IF(BT14>0.005,BT14*Debts!D25/12,0) | BV14: 0 | BW14: =MAX(0,BT14+BU14-BV14) | BX14: =CA13 | BY14: =IF(BX14>0.005,BX14*Debts!D26/12,0) | BZ14: 0 | CA14: =MAX(0,BX14+BY14-BZ14) | CB14: =CE13 | CC14: =IF(CB14>0.005,CB14*Debts!D27/12,0) | CD14: 0 | CE14: =MAX(0,CB14+CC14-CD14) | CF14: =G14+K14+O14+S14+W14+AA14+AE14+AI14+AM14+AQ14+AU14+AY14+BC14+BG14+BK14+BO14+BS14+BW14+CA14+CE14 | CG14: =E14+I14+M14+Q14+U14+Y14+AC14+AG14+AK14+AO14+AS14+AW14+BA14+BE14+BI14+BM14+BQ14+BU14+BY14+CC14 | CH14: =CH13+CG14
B15: 11 | C15: =F15+J15+N15+R15+V15+Z15+AD15+AH15+AL15+AP15+AT15+AX15+BB15+BF15+BJ15+BN15+BR15+BV15+BZ15+CD15 | D15: =G14 | E15: =IF(D15>0.005,D15*Debts!D8/12,0) | F15: 0 | G15: =MAX(0,D15+E15-F15) | H15: =K14 | I15: =IF(H15>0.005,H15*Debts!D9/12,0) | J15: 0 | K15: =MAX(0,H15+I15-J15) | L15: =O14 | M15: =IF(L15>0.005,L15*Debts!D10/12,0) | N15: 0 | O15: =MAX(0,L15+M15-N15) | P15: =S14 | Q15: =IF(P15>0.005,P15*Debts!D11/12,0) | R15: 0 | S15: =MAX(0,P15+Q15-R15) | T15: =W14 | U15: =IF(T15>0.005,T15*Debts!D12/12,0) | V15: 0 | W15: =MAX(0,T15+U15-V15) | X15: =AA14 | Y15: =IF(X15>0.005,X15*Debts!D13/12,0) | Z15: 0 | AA15: =MAX(0,X15+Y15-Z15) | AB15: =AE14 | AC15: =IF(AB15>0.005,AB15*Debts!D14/12,0) | AD15: 0 | AE15: =MAX(0,AB15+AC15-AD15) | AF15: =AI14 | AG15: =IF(AF15>0.005,AF15*Debts!D15/12,0) | AH15: 0 | AI15: =MAX(0,AF15+AG15-AH15) | AJ15: =AM14 | AK15: =IF(AJ15>0.005,AJ15*Debts!D16/12,0) | AL15: 0 | AM15: =MAX(0,AJ15+AK15-AL15) | AN15: =AQ14 | AO15: =IF(AN15>0.005,AN15*Debts!D17/12,0) | AP15: 0 | AQ15: =MAX(0,AN15+AO15-AP15) | AR15: =AU14 | AS15: =IF(AR15>0.005,AR15*Debts!D18/12,0) | AT15: 0 | AU15: =MAX(0,AR15+AS15-AT15) | AV15: =AY14 | AW15: =IF(AV15>0.005,AV15*Debts!D19/12,0) | AX15: 0 | AY15: =MAX(0,AV15+AW15-AX15) | AZ15: =BC14 | BA15: =IF(AZ15>0.005,AZ15*Debts!D20/12,0) | BB15: 0 | BC15: =MAX(0,AZ15+BA15-BB15) | BD15: =BG14 | BE15: =IF(BD15>0.005,BD15*Debts!D21/12,0) | BF15: 0 | BG15: =MAX(0,BD15+BE15-BF15) | BH15: =BK14 | BI15: =IF(BH15>0.005,BH15*Debts!D22/12,0) | BJ15: 0 | BK15: =MAX(0,BH15+BI15-BJ15) | BL15: =BO14 | BM15: =IF(BL15>0.005,BL15*Debts!D23/12,0) | BN15: 0 | BO15: =MAX(0,BL15+BM15-BN15) | BP15: =BS14 | BQ15: =IF(BP15>0.005,BP15*Debts!D24/12,0) | BR15: 0 | BS15: =MAX(0,BP15+BQ15-BR15) | BT15: =BW14 | BU15: =IF(BT15>0.005,BT15*Debts!D25/12,0) | BV15: 0 | BW15: =MAX(0,BT15+BU15-BV15) | BX15: =CA14 | BY15: =IF(BX15>0.005,BX15*Debts!D26/12,0) | BZ15: 0 | CA15: =MAX(0,BX15+BY15-BZ15) | CB15: =CE14 | CC15: =IF(CB15>0.005,CB15*Debts!D27/12,0) | CD15: 0 | CE15: =MAX(0,CB15+CC15-CD15) | CF15: =G15+K15+O15+S15+W15+AA15+AE15+AI15+AM15+AQ15+AU15+AY15+BC15+BG15+BK15+BO15+BS15+BW15+CA15+CE15 | CG15: =E15+I15+M15+Q15+U15+Y15+AC15+AG15+AK15+AO15+AS15+AW15+BA15+BE15+BI15+BM15+BQ15+BU15+BY15+CC15 | CH15: =CH14+CG15
B16: 12 | C16: =F16+J16+N16+R16+V16+Z16+AD16+AH16+AL16+AP16+AT16+AX16+BB16+BF16+BJ16+BN16+BR16+BV16+BZ16+CD16 | D16: =G15 | E16: =IF(D16>0.005,D16*Debts!D8/12,0) | F16: 0 | G16: =MAX(0,D16+E16-F16) | H16: =K15 | I16: =IF(H16>0.005,H16*Debts!D9/12,0) | J16: 0 | K16: =MAX(0,H16+I16-J16) | L16: =O15 | M16: =IF(L16>0.005,L16*Debts!D10/12,0) | N16: 0 | O16: =MAX(0,L16+M16-N16) | P16: =S15 | Q16: =IF(P16>0.005,P16*Debts!D11/12,0) | R16: 0 | S16: =MAX(0,P16+Q16-R16) | T16: =W15 | U16: =IF(T16>0.005,T16*Debts!D12/12,0) | V16: 0 | W16: =MAX(0,T16+U16-V16) | X16: =AA15 | Y16: =IF(X16>0.005,X16*Debts!D13/12,0) | Z16: 0 | AA16: =MAX(0,X16+Y16-Z16) | AB16: =AE15 | AC16: =IF(AB16>0.005,AB16*Debts!D14/12,0) | AD16: 0 | AE16: =MAX(0,AB16+AC16-AD16) | AF16: =AI15 | AG16: =IF(AF16>0.005,AF16*Debts!D15/12,0) | AH16: 0 | AI16: =MAX(0,AF16+AG16-AH16) | AJ16: =AM15 | AK16: =IF(AJ16>0.005,AJ16*Debts!D16/12,0) | AL16: 0 | AM16: =MAX(0,AJ16+AK16-AL16) | AN16: =AQ15 | AO16: =IF(AN16>0.005,AN16*Debts!D17/12,0) | AP16: 0 | AQ16: =MAX(0,AN16+AO16-AP16) | AR16: =AU15 | AS16: =IF(AR16>0.005,AR16*Debts!D18/12,0) | AT16: 0 | AU16: =MAX(0,AR16+AS16-AT16) | AV16: =AY15 | AW16: =IF(AV16>0.005,AV16*Debts!D19/12,0) | AX16: 0 | AY16: =MAX(0,AV16+AW16-AX16) | AZ16: =BC15 | BA16: =IF(AZ16>0.005,AZ16*Debts!D20/12,0) | BB16: 0 | BC16: =MAX(0,AZ16+BA16-BB16) | BD16: =BG15 | BE16: =IF(BD16>0.005,BD16*Debts!D21/12,0) | BF16: 0 | BG16: =MAX(0,BD16+BE16-BF16) | BH16: =BK15 | BI16: =IF(BH16>0.005,BH16*Debts!D22/12,0) | BJ16: 0 | BK16: =MAX(0,BH16+BI16-BJ16) | BL16: =BO15 | BM16: =IF(BL16>0.005,BL16*Debts!D23/12,0) | BN16: 0 | BO16: =MAX(0,BL16+BM16-BN16) | BP16: =BS15 | BQ16: =IF(BP16>0.005,BP16*Debts!D24/12,0) | BR16: 0 | BS16: =MAX(0,BP16+BQ16-BR16) | BT16: =BW15 | BU16: =IF(BT16>0.005,BT16*Debts!D25/12,0) | BV16: 0 | BW16: =MAX(0,BT16+BU16-BV16) | BX16: =CA15 | BY16: =IF(BX16>0.005,BX16*Debts!D26/12,0) | BZ16: 0 | CA16: =MAX(0,BX16+BY16-BZ16) | CB16: =CE15 | CC16: =IF(CB16>0.005,CB16*Debts!D27/12,0) | CD16: 0 | CE16: =MAX(0,CB16+CC16-CD16) | CF16: =G16+K16+O16+S16+W16+AA16+AE16+AI16+AM16+AQ16+AU16+AY16+BC16+BG16+BK16+BO16+BS16+BW16+CA16+CE16 | CG16: =E16+I16+M16+Q16+U16+Y16+AC16+AG16+AK16+AO16+AS16+AW16+BA16+BE16+BI16+BM16+BQ16+BU16+BY16+CC16 | CH16: =CH15+CG16
B17: 13 | C17: =F17+J17+N17+R17+V17+Z17+AD17+AH17+AL17+AP17+AT17+AX17+BB17+BF17+BJ17+BN17+BR17+BV17+BZ17+CD17 | D17: =G16 | E17: =IF(D17>0.005,D17*Debts!D8/12,0) | F17: 0 | G17: =MAX(0,D17+E17-F17) | H17: =K16 | I17: =IF(H17>0.005,H17*Debts!D9/12,0) | J17: 0 | K17: =MAX(0,H17+I17-J17) | L17: =O16 | M17: =IF(L17>0.005,L17*Debts!D10/12,0) | N17: 0 | O17: =MAX(0,L17+M17-N17) | P17: =S16 | Q17: =IF(P17>0.005,P17*Debts!D11/12,0) | R17: 0 | S17: =MAX(0,P17+Q17-R17) | T17: =W16 | U17: =IF(T17>0.005,T17*Debts!D12/12,0) | V17: 0 | W17: =MAX(0,T17+U17-V17) | X17: =AA16 | Y17: =IF(X17>0.005,X17*Debts!D13/12,0) | Z17: 0 | AA17: =MAX(0,X17+Y17-Z17) | AB17: =AE16 | AC17: =IF(AB17>0.005,AB17*Debts!D14/12,0) | AD17: 0 | AE17: =MAX(0,AB17+AC17-AD17) | AF17: =AI16 | AG17: =IF(AF17>0.005,AF17*Debts!D15/12,0) | AH17: 0 | AI17: =MAX(0,AF17+AG17-AH17) | AJ17: =AM16 | AK17: =IF(AJ17>0.005,AJ17*Debts!D16/12,0) | AL17: 0 | AM17: =MAX(0,AJ17+AK17-AL17) | AN17: =AQ16 | AO17: =IF(AN17>0.005,AN17*Debts!D17/12,0) | AP17: 0 | AQ17: =MAX(0,AN17+AO17-AP17) | AR17: =AU16 | AS17: =IF(AR17>0.005,AR17*Debts!D18/12,0) | AT17: 0 | AU17: =MAX(0,AR17+AS17-AT17) | AV17: =AY16 | AW17: =IF(AV17>0.005,AV17*Debts!D19/12,0) | AX17: 0 | AY17: =MAX(0,AV17+AW17-AX17) | AZ17: =BC16 | BA17: =IF(AZ17>0.005,AZ17*Debts!D20/12,0) | BB17: 0 | BC17: =MAX(0,AZ17+BA17-BB17) | BD17: =BG16 | BE17: =IF(BD17>0.005,BD17*Debts!D21/12,0) | BF17: 0 | BG17: =MAX(0,BD17+BE17-BF17) | BH17: =BK16 | BI17: =IF(BH17>0.005,BH17*Debts!D22/12,0) | BJ17: 0 | BK17: =MAX(0,BH17+BI17-BJ17) | BL17: =BO16 | BM17: =IF(BL17>0.005,BL17*Debts!D23/12,0) | BN17: 0 | BO17: =MAX(0,BL17+BM17-BN17) | BP17: =BS16 | BQ17: =IF(BP17>0.005,BP17*Debts!D24/12,0) | BR17: 0 | BS17: =MAX(0,BP17+BQ17-BR17) | BT17: =BW16 | BU17: =IF(BT17>0.005,BT17*Debts!D25/12,0) | BV17: 0 | BW17: =MAX(0,BT17+BU17-BV17) | BX17: =CA16 | BY17: =IF(BX17>0.005,BX17*Debts!D26/12,0) | BZ17: 0 | CA17: =MAX(0,BX17+BY17-BZ17) | CB17: =CE16 | CC17: =IF(CB17>0.005,CB17*Debts!D27/12,0) | CD17: 0 | CE17: =MAX(0,CB17+CC17-CD17) | CF17: =G17+K17+O17+S17+W17+AA17+AE17+AI17+AM17+AQ17+AU17+AY17+BC17+BG17+BK17+BO17+BS17+BW17+CA17+CE17 | CG17: =E17+I17+M17+Q17+U17+Y17+AC17+AG17+AK17+AO17+AS17+AW17+BA17+BE17+BI17+BM17+BQ17+BU17+BY17+CC17 | CH17: =CH16+CG17
B18: 14 | C18: =F18+J18+N18+R18+V18+Z18+AD18+AH18+AL18+AP18+AT18+AX18+BB18+BF18+BJ18+BN18+BR18+BV18+BZ18+CD18 | D18: =G17 | E18: =IF(D18>0.005,D18*Debts!D8/12,0) | F18: 0 | G18: =MAX(0,D18+E18-F18) | H18: =K17 | I18: =IF(H18>0.005,H18*Debts!D9/12,0) | J18: 0 | K18: =MAX(0,H18+I18-J18) | L18: =O17 | M18: =IF(L18>0.005,L18*Debts!D10/12,0) | N18: 0 | O18: =MAX(0,L18+M18-N18) | P18: =S17 | Q18: =IF(P18>0.005,P18*Debts!D11/12,0) | R18: 0 | S18: =MAX(0,P18+Q18-R18) | T18: =W17 | U18: =IF(T18>0.005,T18*Debts!D12/12,0) | V18: 0 | W18: =MAX(0,T18+U18-V18) | X18: =AA17 | Y18: =IF(X18>0.005,X18*Debts!D13/12,0) | Z18: 0 | AA18: =MAX(0,X18+Y18-Z18) | AB18: =AE17 | AC18: =IF(AB18>0.005,AB18*Debts!D14/12,0) | AD18: 0 | AE18: =MAX(0,AB18+AC18-AD18) | AF18: =AI17 | AG18: =IF(AF18>0.005,AF18*Debts!D15/12,0) | AH18: 0 | AI18: =MAX(0,AF18+AG18-AH18) | AJ18: =AM17 | AK18: =IF(AJ18>0.005,AJ18*Debts!D16/12,0) | AL18: 0 | AM18: =MAX(0,AJ18+AK18-AL18) | AN18: =AQ17 | AO18: =IF(AN18>0.005,AN18*Debts!D17/12,0) | AP18: 0 | AQ18: =MAX(0,AN18+AO18-AP18) | AR18: =AU17 | AS18: =IF(AR18>0.005,AR18*Debts!D18/12,0) | AT18: 0 | AU18: =MAX(0,AR18+AS18-AT18) | AV18: =AY17 | AW18: =IF(AV18>0.005,AV18*Debts!D19/12,0) | AX18: 0 | AY18: =MAX(0,AV18+AW18-AX18) | AZ18: =BC17 | BA18: =IF(AZ18>0.005,AZ18*Debts!D20/12,0) | BB18: 0 | BC18: =MAX(0,AZ18+BA18-BB18) | BD18: =BG17 | BE18: =IF(BD18>0.005,BD18*Debts!D21/12,0) | BF18: 0 | BG18: =MAX(0,BD18+BE18-BF18) | BH18: =BK17 | BI18: =IF(BH18>0.005,BH18*Debts!D22/12,0) | BJ18: 0 | BK18: =MAX(0,BH18+BI18-BJ18) | BL18: =BO17 | BM18: =IF(BL18>0.005,BL18*Debts!D23/12,0) | BN18: 0 | BO18: =MAX(0,BL18+BM18-BN18) | BP18: =BS17 | BQ18: =IF(BP18>0.005,BP18*Debts!D24/12,0) | BR18: 0 | BS18: =MAX(0,BP18+BQ18-BR18) | BT18: =BW17 | BU18: =IF(BT18>0.005,BT18*Debts!D25/12,0) | BV18: 0 | BW18: =MAX(0,BT18+BU18-BV18) | BX18: =CA17 | BY18: =IF(BX18>0.005,BX18*Debts!D26/12,0) | BZ18: 0 | CA18: =MAX(0,BX18+BY18-BZ18) | CB18: =CE17 | CC18: =IF(CB18>0.005,CB18*Debts!D27/12,0) | CD18: 0 | CE18: =MAX(0,CB18+CC18-CD18) | CF18: =G18+K18+O18+S18+W18+AA18+AE18+AI18+AM18+AQ18+AU18+AY18+BC18+BG18+BK18+BO18+BS18+BW18+CA18+CE18 | CG18: =E18+I18+M18+Q18+U18+Y18+AC18+AG18+AK18+AO18+AS18+AW18+BA18+BE18+BI18+BM18+BQ18+BU18+BY18+CC18 | CH18: =CH17+CG18
B19: 15 | C19: =F19+J19+N19+R19+V19+Z19+AD19+AH19+AL19+AP19+AT19+AX19+BB19+BF19+BJ19+BN19+BR19+BV19+BZ19+CD19 | D19: =G18 | E19: =IF(D19>0.005,D19*Debts!D8/12,0) | F19: 0 | G19: =MAX(0,D19+E19-F19) | H19: =K18 | I19: =IF(H19>0.005,H19*Debts!D9/12,0) | J19: 0 | K19: =MAX(0,H19+I19-J19) | L19: =O18 | M19: =IF(L19>0.005,L19*Debts!D10/12,0) | N19: 0 | O19: =MAX(0,L19+M19-N19) | P19: =S18 | Q19: =IF(P19>0.005,P19*Debts!D11/12,0) | R19: 0 | S19: =MAX(0,P19+Q19-R19) | T19: =W18 | U19: =IF(T19>0.005,T19*Debts!D12/12,0) | V19: 0 | W19: =MAX(0,T19+U19-V19) | X19: =AA18 | Y19: =IF(X19>0.005,X19*Debts!D13/12,0) | Z19: 0 | AA19: =MAX(0,X19+Y19-Z19) | AB19: =AE18 | AC19: =IF(AB19>0.005,AB19*Debts!D14/12,0) | AD19: 0 | AE19: =MAX(0,AB19+AC19-AD19) | AF19: =AI18 | AG19: =IF(AF19>0.005,AF19*Debts!D15/12,0) | AH19: 0 | AI19: =MAX(0,AF19+AG19-AH19) | AJ19: =AM18 | AK19: =IF(AJ19>0.005,AJ19*Debts!D16/12,0) | AL19: 0 | AM19: =MAX(0,AJ19+AK19-AL19) | AN19: =AQ18 | AO19: =IF(AN19>0.005,AN19*Debts!D17/12,0) | AP19: 0 | AQ19: =MAX(0,AN19+AO19-AP19) | AR19: =AU18 | AS19: =IF(AR19>0.005,AR19*Debts!D18/12,0) | AT19: 0 | AU19: =MAX(0,AR19+AS19-AT19) | AV19: =AY18 | AW19: =IF(AV19>0.005,AV19*Debts!D19/12,0) | AX19: 0 | AY19: =MAX(0,AV19+AW19-AX19) | AZ19: =BC18 | BA19: =IF(AZ19>0.005,AZ19*Debts!D20/12,0) | BB19: 0 | BC19: =MAX(0,AZ19+BA19-BB19) | BD19: =BG18 | BE19: =IF(BD19>0.005,BD19*Debts!D21/12,0) | BF19: 0 | BG19: =MAX(0,BD19+BE19-BF19) | BH19: =BK18 | BI19: =IF(BH19>0.005,BH19*Debts!D22/12,0) | BJ19: 0 | BK19: =MAX(0,BH19+BI19-BJ19) | BL19: =BO18 | BM19: =IF(BL19>0.005,BL19*Debts!D23/12,0) | BN19: 0 | BO19: =MAX(0,BL19+BM19-BN19) | BP19: =BS18 | BQ19: =IF(BP19>0.005,BP19*Debts!D24/12,0) | BR19: 0 | BS19: =MAX(0,BP19+BQ19-BR19) | BT19: =BW18 | BU19: =IF(BT19>0.005,BT19*Debts!D25/12,0) | BV19: 0 | BW19: =MAX(0,BT19+BU19-BV19) | BX19: =CA18 | BY19: =IF(BX19>0.005,BX19*Debts!D26/12,0) | BZ19: 0 | CA19: =MAX(0,BX19+BY19-BZ19) | CB19: =CE18 | CC19: =IF(CB19>0.005,CB19*Debts!D27/12,0) | CD19: 0 | CE19: =MAX(0,CB19+CC19-CD19) | CF19: =G19+K19+O19+S19+W19+AA19+AE19+AI19+AM19+AQ19+AU19+AY19+BC19+BG19+BK19+BO19+BS19+BW19+CA19+CE19 | CG19: =E19+I19+M19+Q19+U19+Y19+AC19+AG19+AK19+AO19+AS19+AW19+BA19+BE19+BI19+BM19+BQ19+BU19+BY19+CC19 | CH19: =CH18+CG19
B20: 16 | C20: =F20+J20+N20+R20+V20+Z20+AD20+AH20+AL20+AP20+AT20+AX20+BB20+BF20+BJ20+BN20+BR20+BV20+BZ20+CD20 | D20: =G19 | E20: =IF(D20>0.005,D20*Debts!D8/12,0) | F20: 0 | G20: =MAX(0,D20+E20-F20) | H20: =K19 | I20: =IF(H20>0.005,H20*Debts!D9/12,0) | J20: 0 | K20: =MAX(0,H20+I20-J20) | L20: =O19 | M20: =IF(L20>0.005,L20*Debts!D10/12,0) | N20: 0 | O20: =MAX(0,L20+M20-N20) | P20: =S19 | Q20: =IF(P20>0.005,P20*Debts!D11/12,0) | R20: 0 | S20: =MAX(0,P20+Q20-R20) | T20: =W19 | U20: =IF(T20>0.005,T20*Debts!D12/12,0) | V20: 0 | W20: =MAX(0,T20+U20-V20) | X20: =AA19 | Y20: =IF(X20>0.005,X20*Debts!D13/12,0) | Z20: 0 | AA20: =MAX(0,X20+Y20-Z20) | AB20: =AE19 | AC20: =IF(AB20>0.005,AB20*Debts!D14/12,0) | AD20: 0 | AE20: =MAX(0,AB20+AC20-AD20) | AF20: =AI19 | AG20: =IF(AF20>0.005,AF20*Debts!D15/12,0) | AH20: 0 | AI20: =MAX(0,AF20+AG20-AH20) | AJ20: =AM19 | AK20: =IF(AJ20>0.005,AJ20*Debts!D16/12,0) | AL20: 0 | AM20: =MAX(0,AJ20+AK20-AL20) | AN20: =AQ19 | AO20: =IF(AN20>0.005,AN20*Debts!D17/12,0) | AP20: 0 | AQ20: =MAX(0,AN20+AO20-AP20) | AR20: =AU19 | AS20: =IF(AR20>0.005,AR20*Debts!D18/12,0) | AT20: 0 | AU20: =MAX(0,AR20+AS20-AT20) | AV20: =AY19 | AW20: =IF(AV20>0.005,AV20*Debts!D19/12,0) | AX20: 0 | AY20: =MAX(0,AV20+AW20-AX20) | AZ20: =BC19 | BA20: =IF(AZ20>0.005,AZ20*Debts!D20/12,0) | BB20: 0 | BC20: =MAX(0,AZ20+BA20-BB20) | BD20: =BG19 | BE20: =IF(BD20>0.005,BD20*Debts!D21/12,0) | BF20: 0 | BG20: =MAX(0,BD20+BE20-BF20) | BH20: =BK19 | BI20: =IF(BH20>0.005,BH20*Debts!D22/12,0) | BJ20: 0 | BK20: =MAX(0,BH20+BI20-BJ20) | BL20: =BO19 | BM20: =IF(BL20>0.005,BL20*Debts!D23/12,0) | BN20: 0 | BO20: =MAX(0,BL20+BM20-BN20) | BP20: =BS19 | BQ20: =IF(BP20>0.005,BP20*Debts!D24/12,0) | BR20: 0 | BS20: =MAX(0,BP20+BQ20-BR20) | BT20: =BW19 | BU20: =IF(BT20>0.005,BT20*Debts!D25/12,0) | BV20: 0 | BW20: =MAX(0,BT20+BU20-BV20) | BX20: =CA19 | BY20: =IF(BX20>0.005,BX20*Debts!D26/12,0) | BZ20: 0 | CA20: =MAX(0,BX20+BY20-BZ20) | CB20: =CE19 | CC20: =IF(CB20>0.005,CB20*Debts!D27/12,0) | CD20: 0 | CE20: =MAX(0,CB20+CC20-CD20) | CF20: =G20+K20+O20+S20+W20+AA20+AE20+AI20+AM20+AQ20+AU20+AY20+BC20+BG20+BK20+BO20+BS20+BW20+CA20+CE20 | CG20: =E20+I20+M20+Q20+U20+Y20+AC20+AG20+AK20+AO20+AS20+AW20+BA20+BE20+BI20+BM20+BQ20+BU20+BY20+CC20 | CH20: =CH19+CG20
B21: 17 | C21: =F21+J21+N21+R21+V21+Z21+AD21+AH21+AL21+AP21+AT21+AX21+BB21+BF21+BJ21+BN21+BR21+BV21+BZ21+CD21 | D21: =G20 | E21: =IF(D21>0.005,D21*Debts!D8/12,0) | F21: 0 | G21: =MAX(0,D21+E21-F21) | H21: =K20 | I21: =IF(H21>0.005,H21*Debts!D9/12,0) | J21: 0 | K21: =MAX(0,H21+I21-J21) | L21: =O20 | M21: =IF(L21>0.005,L21*Debts!D10/12,0) | N21: 0 | O21: =MAX(0,L21+M21-N21) | P21: =S20 | Q21: =IF(P21>0.005,P21*Debts!D11/12,0) | R21: 0 | S21: =MAX(0,P21+Q21-R21) | T21: =W20 | U21: =IF(T21>0.005,T21*Debts!D12/12,0) | V21: 0 | W21: =MAX(0,T21+U21-V21) | X21: =AA20 | Y21: =IF(X21>0.005,X21*Debts!D13/12,0) | Z21: 0 | AA21: =MAX(0,X21+Y21-Z21) | AB21: =AE20 | AC21: =IF(AB21>0.005,AB21*Debts!D14/12,0) | AD21: 0 | AE21: =MAX(0,AB21+AC21-AD21) | AF21: =AI20 | AG21: =IF(AF21>0.005,AF21*Debts!D15/12,0) | AH21: 0 | AI21: =MAX(0,AF21+AG21-AH21) | AJ21: =AM20 | AK21: =IF(AJ21>0.005,AJ21*Debts!D16/12,0) | AL21: 0 | AM21: =MAX(0,AJ21+AK21-AL21) | AN21: =AQ20 | AO21: =IF(AN21>0.005,AN21*Debts!D17/12,0) | AP21: 0 | AQ21: =MAX(0,AN21+AO21-AP21) | AR21: =AU20 | AS21: =IF(AR21>0.005,AR21*Debts!D18/12,0) | AT21: 0 | AU21: =MAX(0,AR21+AS21-AT21) | AV21: =AY20 | AW21: =IF(AV21>0.005,AV21*Debts!D19/12,0) | AX21: 0 | AY21: =MAX(0,AV21+AW21-AX21) | AZ21: =BC20 | BA21: =IF(AZ21>0.005,AZ21*Debts!D20/12,0) | BB21: 0 | BC21: =MAX(0,AZ21+BA21-BB21) | BD21: =BG20 | BE21: =IF(BD21>0.005,BD21*Debts!D21/12,0) | BF21: 0 | BG21: =MAX(0,BD21+BE21-BF21) | BH21: =BK20 | BI21: =IF(BH21>0.005,BH21*Debts!D22/12,0) | BJ21: 0 | BK21: =MAX(0,BH21+BI21-BJ21) | BL21: =BO20 | BM21: =IF(BL21>0.005,BL21*Debts!D23/12,0) | BN21: 0 | BO21: =MAX(0,BL21+BM21-BN21) | BP21: =BS20 | BQ21: =IF(BP21>0.005,BP21*Debts!D24/12,0) | BR21: 0 | BS21: =MAX(0,BP21+BQ21-BR21) | BT21: =BW20 | BU21: =IF(BT21>0.005,BT21*Debts!D25/12,0) | BV21: 0 | BW21: =MAX(0,BT21+BU21-BV21) | BX21: =CA20 | BY21: =IF(BX21>0.005,BX21*Debts!D26/12,0) | BZ21: 0 | CA21: =MAX(0,BX21+BY21-BZ21) | CB21: =CE20 | CC21: =IF(CB21>0.005,CB21*Debts!D27/12,0) | CD21: 0 | CE21: =MAX(0,CB21+CC21-CD21) | CF21: =G21+K21+O21+S21+W21+AA21+AE21+AI21+AM21+AQ21+AU21+AY21+BC21+BG21+BK21+BO21+BS21+BW21+CA21+CE21 | CG21: =E21+I21+M21+Q21+U21+Y21+AC21+AG21+AK21+AO21+AS21+AW21+BA21+BE21+BI21+BM21+BQ21+BU21+BY21+CC21 | CH21: =CH20+CG21
B22: 18 | C22: =F22+J22+N22+R22+V22+Z22+AD22+AH22+AL22+AP22+AT22+AX22+BB22+BF22+BJ22+BN22+BR22+BV22+BZ22+CD22 | D22: =G21 | E22: =IF(D22>0.005,D22*Debts!D8/12,0) | F22: 0 | G22: =MAX(0,D22+E22-F22) | H22: =K21 | I22: =IF(H22>0.005,H22*Debts!D9/12,0) | J22: 0 | K22: =MAX(0,H22+I22-J22) | L22: =O21 | M22: =IF(L22>0.005,L22*Debts!D10/12,0) | N22: 0 | O22: =MAX(0,L22+M22-N22) | P22: =S21 | Q22: =IF(P22>0.005,P22*Debts!D11/12,0) | R22: 0 | S22: =MAX(0,P22+Q22-R22) | T22: =W21 | U22: =IF(T22>0.005,T22*Debts!D12/12,0) | V22: 0 | W22: =MAX(0,T22+U22-V22) | X22: =AA21 | Y22: =IF(X22>0.005,X22*Debts!D13/12,0) | Z22: 0 | AA22: =MAX(0,X22+Y22-Z22) | AB22: =AE21 | AC22: =IF(AB22>0.005,AB22*Debts!D14/12,0) | AD22: 0 | AE22: =MAX(0,AB22+AC22-AD22) | AF22: =AI21 | AG22: =IF(AF22>0.005,AF22*Debts!D15/12,0) | AH22: 0 | AI22: =MAX(0,AF22+AG22-AH22) | AJ22: =AM21 | AK22: =IF(AJ22>0.005,AJ22*Debts!D16/12,0) | AL22: 0 | AM22: =MAX(0,AJ22+AK22-AL22) | AN22: =AQ21 | AO22: =IF(AN22>0.005,AN22*Debts!D17/12,0) | AP22: 0 | AQ22: =MAX(0,AN22+AO22-AP22) | AR22: =AU21 | AS22: =IF(AR22>0.005,AR22*Debts!D18/12,0) | AT22: 0 | AU22: =MAX(0,AR22+AS22-AT22) | AV22: =AY21 | AW22: =IF(AV22>0.005,AV22*Debts!D19/12,0) | AX22: 0 | AY22: =MAX(0,AV22+AW22-AX22) | AZ22: =BC21 | BA22: =IF(AZ22>0.005,AZ22*Debts!D20/12,0) | BB22: 0 | BC22: =MAX(0,AZ22+BA22-BB22) | BD22: =BG21 | BE22: =IF(BD22>0.005,BD22*Debts!D21/12,0) | BF22: 0 | BG22: =MAX(0,BD22+BE22-BF22) | BH22: =BK21 | BI22: =IF(BH22>0.005,BH22*Debts!D22/12,0) | BJ22: 0 | BK22: =MAX(0,BH22+BI22-BJ22) | BL22: =BO21 | BM22: =IF(BL22>0.005,BL22*Debts!D23/12,0) | BN22: 0 | BO22: =MAX(0,BL22+BM22-BN22) | BP22: =BS21 | BQ22: =IF(BP22>0.005,BP22*Debts!D24/12,0) | BR22: 0 | BS22: =MAX(0,BP22+BQ22-BR22) | BT22: =BW21 | BU22: =IF(BT22>0.005,BT22*Debts!D25/12,0) | BV22: 0 | BW22: =MAX(0,BT22+BU22-BV22) | BX22: =CA21 | BY22: =IF(BX22>0.005,BX22*Debts!D26/12,0) | BZ22: 0 | CA22: =MAX(0,BX22+BY22-BZ22) | CB22: =CE21 | CC22: =IF(CB22>0.005,CB22*Debts!D27/12,0) | CD22: 0 | CE22: =MAX(0,CB22+CC22-CD22) | CF22: =G22+K22+O22+S22+W22+AA22+AE22+AI22+AM22+AQ22+AU22+AY22+BC22+BG22+BK22+BO22+BS22+BW22+CA22+CE22 | CG22: =E22+I22+M22+Q22+U22+Y22+AC22+AG22+AK22+AO22+AS22+AW22+BA22+BE22+BI22+BM22+BQ22+BU22+BY22+CC22 | CH22: =CH21+CG22
B23: 19 | C23: =F23+J23+N23+R23+V23+Z23+AD23+AH23+AL23+AP23+AT23+AX23+BB23+BF23+BJ23+BN23+BR23+BV23+BZ23+CD23 | D23: =G22 | E23: =IF(D23>0.005,D23*Debts!D8/12,0) | F23: 0 | G23: =MAX(0,D23+E23-F23) | H23: =K22 | I23: =IF(H23>0.005,H23*Debts!D9/12,0) | J23: 0 | K23: =MAX(0,H23+I23-J23) | L23: =O22 | M23: =IF(L23>0.005,L23*Debts!D10/12,0) | N23: 0 | O23: =MAX(0,L23+M23-N23) | P23: =S22 | Q23: =IF(P23>0.005,P23*Debts!D11/12,0) | R23: 0 | S23: =MAX(0,P23+Q23-R23) | T23: =W22 | U23: =IF(T23>0.005,T23*Debts!D12/12,0) | V23: 0 | W23: =MAX(0,T23+U23-V23) | X23: =AA22 | Y23: =IF(X23>0.005,X23*Debts!D13/12,0) | Z23: 0 | AA23: =MAX(0,X23+Y23-Z23) | AB23: =AE22 | AC23: =IF(AB23>0.005,AB23*Debts!D14/12,0) | AD23: 0 | AE23: =MAX(0,AB23+AC23-AD23) | AF23: =AI22 | AG23: =IF(AF23>0.005,AF23*Debts!D15/12,0) | AH23: 0 | AI23: =MAX(0,AF23+AG23-AH23) | AJ23: =AM22 | AK23: =IF(AJ23>0.005,AJ23*Debts!D16/12,0) | AL23: 0 | AM23: =MAX(0,AJ23+AK23-AL23) | AN23: =AQ22 | AO23: =IF(AN23>0.005,AN23*Debts!D17/12,0) | AP23: 0 | AQ23: =MAX(0,AN23+AO23-AP23) | AR23: =AU22 | AS23: =IF(AR23>0.005,AR23*Debts!D18/12,0) | AT23: 0 | AU23: =MAX(0,AR23+AS23-AT23) | AV23: =AY22 | AW23: =IF(AV23>0.005,AV23*Debts!D19/12,0) | AX23: 0 | AY23: =MAX(0,AV23+AW23-AX23) | AZ23: =BC22 | BA23: =IF(AZ23>0.005,AZ23*Debts!D20/12,0) | BB23: 0 | BC23: =MAX(0,AZ23+BA23-BB23) | BD23: =BG22 | BE23: =IF(BD23>0.005,BD23*Debts!D21/12,0) | BF23: 0 | BG23: =MAX(0,BD23+BE23-BF23) | BH23: =BK22 | BI23: =IF(BH23>0.005,BH23*Debts!D22/12,0) | BJ23: 0 | BK23: =MAX(0,BH23+BI23-BJ23) | BL23: =BO22 | BM23: =IF(BL23>0.005,BL23*Debts!D23/12,0) | BN23: 0 | BO23: =MAX(0,BL23+BM23-BN23) | BP23: =BS22 | BQ23: =IF(BP23>0.005,BP23*Debts!D24/12,0) | BR23: 0 | BS23: =MAX(0,BP23+BQ23-BR23) | BT23: =BW22 | BU23: =IF(BT23>0.005,BT23*Debts!D25/12,0) | BV23: 0 | BW23: =MAX(0,BT23+BU23-BV23) | BX23: =CA22 | BY23: =IF(BX23>0.005,BX23*Debts!D26/12,0) | BZ23: 0 | CA23: =MAX(0,BX23+BY23-BZ23) | CB23: =CE22 | CC23: =IF(CB23>0.005,CB23*Debts!D27/12,0) | CD23: 0 | CE23: =MAX(0,CB23+CC23-CD23) | CF23: =G23+K23+O23+S23+W23+AA23+AE23+AI23+AM23+AQ23+AU23+AY23+BC23+BG23+BK23+BO23+BS23+BW23+CA23+CE23 | CG23: =E23+I23+M23+Q23+U23+Y23+AC23+AG23+AK23+AO23+AS23+AW23+BA23+BE23+BI23+BM23+BQ23+BU23+BY23+CC23 | CH23: =CH22+CG23
B24: 20 | C24: =F24+J24+N24+R24+V24+Z24+AD24+AH24+AL24+AP24+AT24+AX24+BB24+BF24+BJ24+BN24+BR24+BV24+BZ24+CD24 | D24: =G23 | E24: =IF(D24>0.005,D24*Debts!D8/12,0) | F24: 0 | G24: =MAX(0,D24+E24-F24) | H24: =K23 | I24: =IF(H24>0.005,H24*Debts!D9/12,0) | J24: 0 | K24: =MAX(0,H24+I24-J24) | L24: =O23 | M24: =IF(L24>0.005,L24*Debts!D10/12,0) | N24: 0 | O24: =MAX(0,L24+M24-N24) | P24: =S23 | Q24: =IF(P24>0.005,P24*Debts!D11/12,0) | R24: 0 | S24: =MAX(0,P24+Q24-R24) | T24: =W23 | U24: =IF(T24>0.005,T24*Debts!D12/12,0) | V24: 0 | W24: =MAX(0,T24+U24-V24) | X24: =AA23 | Y24: =IF(X24>0.005,X24*Debts!D13/12,0) | Z24: 0 | AA24: =MAX(0,X24+Y24-Z24) | AB24: =AE23 | AC24: =IF(AB24>0.005,AB24*Debts!D14/12,0) | AD24: 0 | AE24: =MAX(0,AB24+AC24-AD24) | AF24: =AI23 | AG24: =IF(AF24>0.005,AF24*Debts!D15/12,0) | AH24: 0 | AI24: =MAX(0,AF24+AG24-AH24) | AJ24: =AM23 | AK24: =IF(AJ24>0.005,AJ24*Debts!D16/12,0) | AL24: 0 | AM24: =MAX(0,AJ24+AK24-AL24) | AN24: =AQ23 | AO24: =IF(AN24>0.005,AN24*Debts!D17/12,0) | AP24: 0 | AQ24: =MAX(0,AN24+AO24-AP24) | AR24: =AU23 | AS24: =IF(AR24>0.005,AR24*Debts!D18/12,0) | AT24: 0 | AU24: =MAX(0,AR24+AS24-AT24) | AV24: =AY23 | AW24: =IF(AV24>0.005,AV24*Debts!D19/12,0) | AX24: 0 | AY24: =MAX(0,AV24+AW24-AX24) | AZ24: =BC23 | BA24: =IF(AZ24>0.005,AZ24*Debts!D20/12,0) | BB24: 0 | BC24: =MAX(0,AZ24+BA24-BB24) | BD24: =BG23 | BE24: =IF(BD24>0.005,BD24*Debts!D21/12,0) | BF24: 0 | BG24: =MAX(0,BD24+BE24-BF24) | BH24: =BK23 | BI24: =IF(BH24>0.005,BH24*Debts!D22/12,0) | BJ24: 0 | BK24: =MAX(0,BH24+BI24-BJ24) | BL24: =BO23 | BM24: =IF(BL24>0.005,BL24*Debts!D23/12,0) | BN24: 0 | BO24: =MAX(0,BL24+BM24-BN24) | BP24: =BS23 | BQ24: =IF(BP24>0.005,BP24*Debts!D24/12,0) | BR24: 0 | BS24: =MAX(0,BP24+BQ24-BR24) | BT24: =BW23 | BU24: =IF(BT24>0.005,BT24*Debts!D25/12,0) | BV24: 0 | BW24: =MAX(0,BT24+BU24-BV24) | BX24: =CA23 | BY24: =IF(BX24>0.005,BX24*Debts!D26/12,0) | BZ24: 0 | CA24: =MAX(0,BX24+BY24-BZ24) | CB24: =CE23 | CC24: =IF(CB24>0.005,CB24*Debts!D27/12,0) | CD24: 0 | CE24: =MAX(0,CB24+CC24-CD24) | CF24: =G24+K24+O24+S24+W24+AA24+AE24+AI24+AM24+AQ24+AU24+AY24+BC24+BG24+BK24+BO24+BS24+BW24+CA24+CE24 | CG24: =E24+I24+M24+Q24+U24+Y24+AC24+AG24+AK24+AO24+AS24+AW24+BA24+BE24+BI24+BM24+BQ24+BU24+BY24+CC24 | CH24: =CH23+CG24
B25: 21 | C25: =F25+J25+N25+R25+V25+Z25+AD25+AH25+AL25+AP25+AT25+AX25+BB25+BF25+BJ25+BN25+BR25+BV25+BZ25+CD25 | D25: =G24 | E25: =IF(D25>0.005,D25*Debts!D8/12,0) | F25: 0 | G25: =MAX(0,D25+E25-F25) | H25: =K24 | I25: =IF(H25>0.005,H25*Debts!D9/12,0) | J25: 0 | K25: =MAX(0,H25+I25-J25) | L25: =O24 | M25: =IF(L25>0.005,L25*Debts!D10/12,0) | N25: 0 | O25: =MAX(0,L25+M25-N25) | P25: =S24 | Q25: =IF(P25>0.005,P25*Debts!D11/12,0) | R25: 0 | S25: =MAX(0,P25+Q25-R25) | T25: =W24 | U25: =IF(T25>0.005,T25*Debts!D12/12,0) | V25: 0 | W25: =MAX(0,T25+U25-V25) | X25: =AA24 | Y25: =IF(X25>0.005,X25*Debts!D13/12,0) | Z25: 0 | AA25: =MAX(0,X25+Y25-Z25) | AB25: =AE24 | AC25: =IF(AB25>0.005,AB25*Debts!D14/12,0) | AD25: 0 | AE25: =MAX(0,AB25+AC25-AD25) | AF25: =AI24 | AG25: =IF(AF25>0.005,AF25*Debts!D15/12,0) | AH25: 0 | AI25: =MAX(0,AF25+AG25-AH25) | AJ25: =AM24 | AK25: =IF(AJ25>0.005,AJ25*Debts!D16/12,0) | AL25: 0 | AM25: =MAX(0,AJ25+AK25-AL25) | AN25: =AQ24 | AO25: =IF(AN25>0.005,AN25*Debts!D17/12,0) | AP25: 0 | AQ25: =MAX(0,AN25+AO25-AP25) | AR25: =AU24 | AS25: =IF(AR25>0.005,AR25*Debts!D18/12,0) | AT25: 0 | AU25: =MAX(0,AR25+AS25-AT25) | AV25: =AY24 | AW25: =IF(AV25>0.005,AV25*Debts!D19/12,0) | AX25: 0 | AY25: =MAX(0,AV25+AW25-AX25) | AZ25: =BC24 | BA25: =IF(AZ25>0.005,AZ25*Debts!D20/12,0) | BB25: 0 | BC25: =MAX(0,AZ25+BA25-BB25) | BD25: =BG24 | BE25: =IF(BD25>0.005,BD25*Debts!D21/12,0) | BF25: 0 | BG25: =MAX(0,BD25+BE25-BF25) | BH25: =BK24 | BI25: =IF(BH25>0.005,BH25*Debts!D22/12,0) | BJ25: 0 | BK25: =MAX(0,BH25+BI25-BJ25) | BL25: =BO24 | BM25: =IF(BL25>0.005,BL25*Debts!D23/12,0) | BN25: 0 | BO25: =MAX(0,BL25+BM25-BN25) | BP25: =BS24 | BQ25: =IF(BP25>0.005,BP25*Debts!D24/12,0) | BR25: 0 | BS25: =MAX(0,BP25+BQ25-BR25) | BT25: =BW24 | BU25: =IF(BT25>0.005,BT25*Debts!D25/12,0) | BV25: 0 | BW25: =MAX(0,BT25+BU25-BV25) | BX25: =CA24 | BY25: =IF(BX25>0.005,BX25*Debts!D26/12,0) | BZ25: 0 | CA25: =MAX(0,BX25+BY25-BZ25) | CB25: =CE24 | CC25: =IF(CB25>0.005,CB25*Debts!D27/12,0) | CD25: 0 | CE25: =MAX(0,CB25+CC25-CD25) | CF25: =G25+K25+O25+S25+W25+AA25+AE25+AI25+AM25+AQ25+AU25+AY25+BC25+BG25+BK25+BO25+BS25+BW25+CA25+CE25 | CG25: =E25+I25+M25+Q25+U25+Y25+AC25+AG25+AK25+AO25+AS25+AW25+BA25+BE25+BI25+BM25+BQ25+BU25+BY25+CC25 | CH25: =CH24+CG25
